<?xml version="1.0"?>
<robot name="px100" xmlns:xacro="http://ros.org/wiki/xacro">

  <gazebo>
    <plugin name="gazebo_ros_control" filename="libgazebo_ros_control.so">
    </plugin>
  </gazebo>
  <xacro:arg name="robot_name" default = "px100"/>
  <xacro:arg name="base_link_frame" default="${arm_base_frame}"/>
  <xacro:arg name="show_ar_tag" default="false"/>
  <xacro:arg name="show_gripper_bar" default="true"/>
  <xacro:arg name="show_gripper_fingers" default="true"/>
  <xacro:arg name="use_world_frame" default="false"/>
  <xacro:arg name="load_gazebo_configs" default="false"/>
  <xacro:property name="pi_offset" value="0.00001"/>

  <joint name="arm_attachment" type="fixed" >
    <xacro:insert_block name="arm_origin" />
    <parent link="${attachment_frame}"/>
    <child link="$(arg robot_name)/$(arg base_link_frame)"/>
  </joint>

  <link name="$(arg robot_name)/$(arg base_link_frame)">
    <visual>
      <origin rpy="0 0 ${pi/2}" xyz="0 0 0"/>
      <geometry>
        <mesh filename="package://dr_phil_description/meshes/px100_meshes/px100_1_base.stl" scale="0.001 0.001 0.001"/>
      </geometry>
      <material name="black"/>
    </visual>
    <collision>
      <origin rpy="0 0 ${pi/2}" xyz="0 0 0"/>
      <geometry>
        <mesh filename="package://dr_phil_description/meshes/px100_meshes/px100_1_base.stl" scale="0.001 0.001 0.001"/>
      </geometry>
    </collision>
    <inertial>
      <origin rpy="0 0 ${pi/2}" xyz="-0.0332053000 0.0008915770 0.0211913000"/>
      <mass value="0.395887" />
      <inertia ixx="0.0010650000" iyy="0.0003332000" izz="0.0012080000" ixy="-0.0000130300" ixz="0.0000018614" iyz="0.0000409200" />
    </inertial>
  </link>

  <joint name="waist" type="revolute">
    <axis xyz="0 0 1"/>
    <limit effort="1" lower="${-pi + pi_offset}" upper="${pi - pi_offset}" velocity="${pi}"/>
    <origin rpy="0 0 0" xyz="0 0 0.05085"/>
    <parent link="$(arg robot_name)/$(arg base_link_frame)"/>
    <child link="$(arg robot_name)/shoulder_link"/>
    <dynamics friction="0.1"/>
  </joint>

  <transmission name="trans_waist">
    <type>transmission_interface/SimpleTransmission</type>
    <joint name="waist">
      <hardwareInterface>hardware_interface/EffortJointInterface</hardwareInterface>
    </joint>
    <actuator name="waist_motor">
      <mechanicalReduction>1</mechanicalReduction>
    </actuator>
  </transmission>

  <link name="$(arg robot_name)/shoulder_link">
    <visual>
      <origin rpy="0 0 ${pi/2}" xyz="0 0 -0.0022"/>
      <geometry>
        <mesh filename="package://dr_phil_description/meshes/px100_meshes/px100_2_shoulder.stl" scale="0.001 0.001 0.001"/>
      </geometry>
      <material name="black"/>
    </visual>
    <collision>
      <origin rpy="0 0 ${pi/2}" xyz="0 0 -0.0022"/>
      <geometry>
        <mesh filename="package://dr_phil_description/meshes/px100_meshes/px100_2_shoulder.stl" scale="0.001 0.001 0.001"/>
      </geometry>
    </collision>
    <inertial>
      <origin rpy="0 0 ${pi/2}" xyz="0.0000111169 -0.0003605640 0.0284598000"/>
      <mass value="0.072587" />
      <inertia ixx="0.0000231000" iyy="0.0000253500" izz="0.0000144200" ixy="0.0000000003" ixz="0.0000001606" iyz="-0.0000000206" />
    </inertial>
  </link>

  <joint name="shoulder" type="revolute">
    <axis xyz="0 1 0"/>
    <limit effort="2" lower="${radians(-111)}" upper="${radians(107)}" velocity="${pi}"/>
    <origin rpy="0 0 0" xyz="0 0 0.04225"/>
    <parent link="$(arg robot_name)/shoulder_link"/>
    <child link="$(arg robot_name)/upper_arm_link"/>
    <dynamics friction="0.1"/>
  </joint>

  <transmission name="trans_shoulder">
    <type>transmission_interface/SimpleTransmission</type>
    <joint name="shoulder">
      <hardwareInterface>hardware_interface/EffortJointInterface</hardwareInterface>
    </joint>
    <actuator name="shoulder_motor">
      <mechanicalReduction>1</mechanicalReduction>
    </actuator>
  </transmission>

  <link name="$(arg robot_name)/upper_arm_link">
    <visual>
      <origin rpy="0 0 ${pi/2}" xyz="0 0 0"/>
      <geometry>
        <mesh filename="package://dr_phil_description/meshes/px100_meshes/px100_3_upper_arm.stl" scale="0.001 0.001 0.001"/>
      </geometry>
      <material name="black"/>
    </visual>
    <collision>
      <origin rpy="0 0 ${pi/2}" xyz="0 0 0"/>
      <geometry>
        <mesh filename="package://dr_phil_description/meshes/px100_meshes/px100_3_upper_arm.stl" scale="0.001 0.001 0.001"/>
      </geometry>
    </collision>
    <inertial>
      <origin rpy="0 0 ${pi/2}" xyz="0.0161976963 -0.0002929352 0.0877230000"/>
      <mass value="0.082923" />
      <inertia ixx="0.0000800600" iyy="0.0000745900" izz="0.0000368500" ixy="-0.0000002144" ixz="0.0000002982" iyz="0.0000165700" />
    </inertial>
  </link>

  <joint name="elbow" type="revolute">
    <axis xyz="0 1 0"/>
    <limit effort="2" lower="${radians(-121)}" upper="${radians(92)}" velocity="${pi}"/>
    <origin rpy="0 0 0" xyz="0.035 0 0.1"/>
    <parent link="$(arg robot_name)/upper_arm_link"/>
    <child link="$(arg robot_name)/forearm_link"/>
    <dynamics friction="0.1"/>
  </joint>

  <transmission name="trans_elbow">
    <type>transmission_interface/SimpleTransmission</type>
    <joint name="elbow">
      <hardwareInterface>hardware_interface/EffortJointInterface</hardwareInterface>
    </joint>
    <actuator name="elbow_motor">
      <mechanicalReduction>1</mechanicalReduction>
    </actuator>
  </transmission>

  <link name="$(arg robot_name)/forearm_link">
    <visual>
      <origin rpy="0 0 ${pi/2}" xyz="0 0 0"/>
      <geometry>
        <mesh filename="package://dr_phil_description/meshes/px100_meshes/px100_4_forearm.stl" scale="0.001 0.001 0.001"/>
      </geometry>
      <material name="black"/>
    </visual>
    <collision>
      <origin rpy="0 0 ${pi/2}" xyz="0 0 0"/>
      <geometry>
        <mesh filename="package://dr_phil_description/meshes/px100_meshes/px100_4_forearm.stl" scale="0.001 0.001 0.001"/>
      </geometry>
    </collision>
    <inertial>
      <origin rpy="0 0 ${pi/2}" xyz="0.0773720000 -0.0003324882 0.0000000000"/>
      <mass value="0.073058" />
      <inertia ixx="0.0000533800" iyy="0.0000165300" izz="0.0000603500" ixy="-0.0000003073" ixz="0.0000000000" iyz="0.0000000000" />
    </inertial>
  </link>

  <joint name="wrist_angle" type="revolute">
    <axis xyz="0 1 0"/>
    <limit effort="1" lower="${radians(-100)}" upper="${radians(123)}"  velocity="${pi}"/>
    <origin rpy="0 0 0" xyz="0.1 0 0"/>
    <parent link="$(arg robot_name)/forearm_link"/>
    <child link="$(arg robot_name)/gripper_link"/>
    <dynamics friction="0.1"/>
  </joint>

  <transmission name="trans_wrist_angle">
    <type>transmission_interface/SimpleTransmission</type>
    <joint name="wrist_angle">
      <hardwareInterface>hardware_interface/EffortJointInterface</hardwareInterface>
    </joint>
    <actuator name="wrist_angle_motor">
      <mechanicalReduction>1</mechanicalReduction>
    </actuator>
  </transmission>

  <link name="$(arg robot_name)/gripper_link">
    <visual>
      <origin rpy="0 0 ${pi/2}" xyz="0 0 0"/>
      <geometry>
        <mesh filename="package://dr_phil_description/meshes/px100_meshes/px100_5_gripper.stl" scale="0.001 0.001 0.001"/>
      </geometry>
      <material name="black"/>
    </visual>
    <collision>
      <origin rpy="0 0 ${pi/2}" xyz="0 0 0"/>
      <geometry>
        <mesh filename="package://dr_phil_description/meshes/px100_meshes/px100_5_gripper.stl" scale="0.001 0.001 0.001"/>
      </geometry>
    </collision>
    <inertial>
      <origin rpy="0 0 ${pi/2}" xyz="0.0446910000 0.0000000000 0.0113540000"/>
      <mass value="0.069929" />
      <inertia ixx="0.0000226800" iyy="0.0000204400" izz="0.0000197400" ixy="0.0000000000" ixz="0.0000000000" iyz="0.0000008485" />
    </inertial>
  </link>

  <joint name="ee_arm" type="fixed">
    <axis xyz="1 0 0"/>
    <origin rpy="0 0 0" xyz="0.063 0 0"/>
    <parent link="$(arg robot_name)/gripper_link"/>
    <child link="$(arg robot_name)/ee_arm_link"/>
  </joint>

  <link name="$(arg robot_name)/ee_arm_link">
    <inertial>
      <mass value="0.001" />
      <inertia ixx="0.001" iyy="0.001" izz="0.001" ixy="0" ixz="0" iyz="0" />
    </inertial>
  </link>

  <joint name="gripper" type="continuous">
    <axis xyz="1 0 0"/>
    <limit effort="1" velocity="${pi}"/>
    <origin rpy="0 0 0" xyz="0.0055 0 0"/>
    <parent link="$(arg robot_name)/ee_arm_link"/>
    <child link="$(arg robot_name)/gripper_prop_link"/>
    <dynamics friction="0.1"/>
  </joint>

  <joint name="$(arg robot_name)/led_joint" type="fixed"> 
  <origin xyz="0.044 0.019 0.0345" rpy="0 0 0"/> 
  <parent link="$(arg robot_name)/gripper_link"/>
  <child link="$(arg robot_name)/led_link"/> </joint>
  
<link name="$(arg robot_name)/led_link">
   <visual>
      <origin rpy="0 0 0" xyz="0 0.0 0.0"/>
      <geometry>
        <mesh filename="package://dr_phil_description/meshes/spray_components/8_5mm_nozzle.stl" scale="0.001 0.001 0.001"/>
      </geometry>
      <material name="black"/>
    </visual>
   <collision>
      <origin rpy="0 0 0" xyz="0 0 0"/>
      <geometry>
        <mesh filename="package://dr_phil_description/meshes/spray_components/8_5mm_nozzle.stl" scale="0.001 0.001 0.001"/>
      </geometry>
    </collision>

    <inertial>
      <origin rpy="0 0 0" xyz="0 0 0"/>
      <mass value="0.002" />
      <inertia ixx="0.00" iyy="0.00" izz="0.000" ixy="0.0000000000" ixz="0.0000000000" iyz="0" />
    </inertial>
  </link>
  
  <joint name="$(arg robot_name)/led_joint1" type="fixed"> 
  <origin xyz="0.044 0.019 0.0345" rpy="${-pi/2} 0 ${-pi/2}"/> 
  <parent link="$(arg robot_name)/gripper_link"/>
  <child link="$(arg robot_name)/led_link1"/> </joint>
  
<link name="$(arg robot_name)/led_link1">
  </link>
  
    <gazebo reference="$(arg robot_name)/gripper_link">
    <sensor type="depth" name="depth_camera">
    <pose>0.06645 0 0.043 0 0 0</pose>
      <update_rate>1</update_rate>
      <camera>
        <horizontal_fov>${pi/6}</horizontal_fov>
        <image>
          <width>640</width>
          <height>480</height>
          <format>R8G8B8</format>
        </image>
        <clip>
          <near>0.02</near>
          <far>1</far>
        </clip>
      </camera>
          <plugin name="camera_plugin" filename="libgazebo_ros_openni_kinect.so">
          <baseline>0.2</baseline>
          <alwaysOn>true</alwaysOn>
          <!-- Keep this zero, update_rate in the parent <sensor> tag
            will control the frame rate. -->
          <updateRate>0.0</updateRate>
          <cameraName>depth_camera</cameraName>
          <imageTopicName>/depth_camera/color/image_raw</imageTopicName>
          <cameraInfoTopicName>/depth_camera/color/camera_info</cameraInfoTopicName>
          <depthImageTopicName>/depth_camera/depth/image_raw</depthImageTopicName>
          <depthImageCameraInfoTopicName>/depth_camera/depth/camera_info</depthImageCameraInfoTopicName>
          <pointCloudTopicName>/depth_camera/depth/points</pointCloudTopicName>
          <frameName>odom</frameName>
          <pointCloudCutoff>0.0</pointCloudCutoff>
          <pointCloudCutoffMax>1.0</pointCloudCutoffMax>
          <distortionK1>0</distortionK1>
          <distortionK2>0</distortionK2>
          <distortionK3>0</distortionK3>
          <distortionT1>0</distortionT1>
          <distortionT2>0</distortionT2>
          <CxPrime>0</CxPrime>
          <Cx>0</Cx>
          <Cy>0</Cy>
          <focalLength>0</focalLength>
          <hackBaseline>0</hackBaseline>
        </plugin>
    </sensor>
  </gazebo>
  
  <gazebo reference="$(arg robot_name)/gripper_link">
  <light name ='led' type = 'spot'>
    <pose>0.06645 0 0.043 0 ${-pi/2} 0</pose><!--you can place light position here ,and it is useless to give position in link-->
    <attenuation>
            <range>0</range>
          </attenuation>
          <diffuse>1 1 1 0</diffuse>
          <specular>1 1 1 0</specular>
          <spot>
            <inner_angle>${pi/6}</inner_angle>
            <outer_angle>${pi/6}</outer_angle>
            <falloff>1</falloff>
          </spot>
          <cast_shadows>1</cast_shadows>
  </light>
  </gazebo>
  
  <transmission name="trans_gripper">
    <type>transmission_interface/SimpleTransmission</type>
    <joint name="gripper">
      <hardwareInterface>hardware_interface/EffortJointInterface</hardwareInterface>
    </joint>
    <actuator name="gripper_motor">
      <mechanicalReduction>1</mechanicalReduction>
    </actuator>
  </transmission>

  <link name="$(arg robot_name)/gripper_prop_link">
    <visual>
      <origin rpy="0 0 ${pi/2}" xyz="-0.0685 0 0"/>
      <geometry>
        <mesh filename="package://dr_phil_description/meshes/px100_meshes/px100_6_gripper_prop.stl" scale="0.001 0.001 0.001"/>
      </geometry>
      <material name="black"/>
    </visual>
    <collision>
      <origin rpy="0 0 ${pi/2}" xyz="-0.0685 0 0"/>
      <geometry>
        <mesh filename="package://dr_phil_description/meshes/px100_meshes/px100_6_gripper_prop.stl" scale="0.001 0.001 0.001"/>
      </geometry>
    </collision>
    <inertial>
      <origin rpy="0 0 ${pi/2}" xyz="0.0008460000 -0.0000019330 0.0000420000"/>
      <mass value="0.00434" />
      <inertia ixx="0.0000005923" iyy="0.0000011156" izz="0.0000005743" ixy="0.0000000000" ixz="0.0000003195" iyz="-0.0000000004" />
    </inertial>
  </link>

  <!-- If the AR tag is being used, then add the AR tag mount -->

  <xacro:if value="$(arg show_ar_tag)">

    <joint name="ar_tag" type="fixed">
      <axis xyz="0 0 0"/>
      <origin rpy="0 0 0" xyz="-0.017 0 0.04155"/>
      <parent link="$(arg robot_name)/ee_arm_link"/>
      <child link="$(arg robot_name)/ar_tag_link"/>
    </joint>

    <link name="$(arg robot_name)/ar_tag_link">
      <visual>
        <origin rpy="0 0 0" xyz="0 0 0"/>
        <geometry>
          <mesh filename="package://dr_phil_description/meshes/px100_meshes/px100_9_ar_tag.stl" scale="0.001 0.001 0.001"/>
        </geometry>
        <material name="black"/>
      </visual>
      <collision>
        <origin rpy="0 0 0" xyz="0 0 0"/>
        <geometry>
          <mesh filename="package://dr_phil_description/meshes/px100_meshes/px100_9_ar_tag.stl" scale="0.001 0.001 0.001"/>
        </geometry>
      </collision>
      <inertial>
        <origin rpy="0 0 0" xyz="0 0 -0.00315"/>
        <mass value="0.016507"/>
        <inertia ixx="0.000003084" ixy="0" ixz="0" iyy="0.000003084" iyz="0" izz="0.000006059"/>
      </inertial>
    </link>

  </xacro:if>

  <!-- If the gripper bar is being used, then also add the gripper bar -->

  <xacro:if value="$(arg show_gripper_bar)">

    <joint name="gripper_bar" type="fixed">
      <axis xyz="1 0 0"/>
      <origin rpy="0 0 0" xyz="0 0 0"/>
      <parent link="$(arg robot_name)/ee_arm_link"/>
      <child link="$(arg robot_name)/gripper_bar_link"/>
    </joint>

    <link name="$(arg robot_name)/gripper_bar_link">
      <visual>
        <origin rpy="0 0 ${pi/2}" xyz="-0.063 0 0"/>
        <geometry>
          <mesh filename="package://dr_phil_description/meshes/px100_meshes/px100_7_gripper_bar.stl" scale="0.001 0.001 0.001"/>
        </geometry>
        <material name="black"/>
      </visual>
      <collision>
        <origin rpy="0 0 ${pi/2}" xyz="-0.063 0 0"/>
        <geometry>
          <mesh filename="package://dr_phil_description/meshes/px100_meshes/px100_7_gripper_bar.stl" scale="0.001 0.001 0.001"/>
        </geometry>
      </collision>
      <inertial>
        <origin rpy="0 0 ${pi/2}" xyz="0.0096870000 0.0000005660 0.0049620000"/>
        <mass value="0.034199" />
        <inertia ixx="0.0000074125" iyy="0.0000284300" izz="0.0000286000" ixy="-0.0000000008" ixz="-0.0000000006" iyz="-0.0000013889" />
      </inertial>
    </link>

    <joint name="ee_bar" type="fixed">
      <axis xyz="1 0 0"/>
      <origin rpy="0 0 0" xyz="0.023 0 0"/>
      <parent link="$(arg robot_name)/gripper_bar_link"/>
      <child link="$(arg robot_name)/fingers_link"/>
    </joint>

    <link name="$(arg robot_name)/fingers_link">
      <inertial>
        <mass value="0.001" />
        <inertia ixx="0.001" iyy="0.001" izz="0.001" ixy="0" ixz="0" iyz="0" />
      </inertial>
    </link>

    <!-- If the gripper fingers are being used, add those as well -->

    <xacro:if value="$(arg show_gripper_fingers)">

      <joint name="left_finger" type="prismatic">
        <axis xyz="0 1 0"/>
        <limit effort="5" lower="0.015" upper="0.037" velocity="1"/>
        <origin rpy="0 0 0" xyz="0 0 0"/>
        <parent link="$(arg robot_name)/fingers_link"/>
        <child link="$(arg robot_name)/left_finger_link"/>
        <dynamics friction="0.1"/>
      </joint>

      <transmission name="trans_left_finger">
        <type>transmission_interface/SimpleTransmission</type>
        <joint name="left_finger">
          <hardwareInterface>hardware_interface/EffortJointInterface</hardwareInterface>
        </joint>
        <actuator name="left_finger_motor">
          <mechanicalReduction>1</mechanicalReduction>
        </actuator>
      </transmission>

      <link name="$(arg robot_name)/left_finger_link">
        <visual>
          <origin rpy="${pi} ${pi} 0" xyz="0 0.005 0"/>
          <geometry>
            <mesh filename="package://dr_phil_description/meshes/px100_meshes/px100_8_gripper_finger.stl" scale="0.001 0.001 0.001"/>
          </geometry>
          <material name="black"/>
        </visual>
        <collision>
          <origin rpy="${pi} ${pi} 0" xyz="0 0.005 0"/>
          <geometry>
            <mesh filename="package://dr_phil_description/meshes/px100_meshes/px100_8_gripper_finger.stl" scale="0.001 0.001 0.001"/>
          </geometry>
        </collision>
        <inertial>
          <origin rpy="${pi} ${pi} ${pi/2}" xyz="0.0138160000 0.0000000000 0.0000000000"/>
           <mass value="0.016246" />
          <inertia ixx="0.0000047310" iyy="0.0000015506" izz="0.0000037467" ixy="-0.0000004560" ixz="0.0000000000" iyz="0.0000000000" />
        </inertial>
      </link>

      <joint name="right_finger" type="prismatic">
        <axis xyz="0 1 0"/>
        <limit effort="5" lower="-0.037" upper="-0.015" velocity="1"/>
        <origin rpy="0 0 0" xyz="0 0 0"/>
        <parent link="$(arg robot_name)/fingers_link"/>
        <child link="$(arg robot_name)/right_finger_link"/>
        <dynamics friction="0.1"/>
        <xacro:unless value="$(arg load_gazebo_configs)">
          <mimic joint="left_finger" multiplier="-1" offset="0"/>
        </xacro:unless>
      </joint>

      <transmission name="trans_right_finger">
        <type>transmission_interface/SimpleTransmission</type>
        <joint name="right_finger">
          <hardwareInterface>hardware_interface/EffortJointInterface</hardwareInterface>
        </joint>
        <actuator name="right_finger_motor">
          <mechanicalReduction>1</mechanicalReduction>
        </actuator>
      </transmission>

      <link name="$(arg robot_name)/right_finger_link">
        <visual>
          <origin rpy="0 ${pi} 0" xyz="0 -0.005 0"/>
          <geometry>
            <mesh filename="package://dr_phil_description/meshes/px100_meshes/px100_8_gripper_finger.stl" scale="0.001 0.001 0.001"/>
          </geometry>
          <material name="black"/>
        </visual>
        <collision>
          <origin rpy="0 ${pi} 0" xyz="0 -0.005 0"/>
          <geometry>
            <mesh filename="package://dr_phil_description/meshes/px100_meshes/px100_8_gripper_finger.stl" scale="0.001 0.001 0.001"/>
          </geometry>
        </collision>
        <inertial>
          <origin rpy="0 ${pi} ${pi/2}" xyz="0.0138160000 0.0000000000  0.0000000000"/>
          <mass value="0.016246" />
          <inertia ixx="0.0000047310" iyy="0.0000015506" izz="0.0000037467" ixy="0.0000004560" ixz="0.0000000000" iyz="0.0000000000" />
        </inertial>
      </link>

      <joint name="ee_gripper" type="fixed">
        <axis xyz="1 0 0"/>
        <origin rpy="0 0 0" xyz="0.027575 0 0"/>
        <parent link="$(arg robot_name)/fingers_link"/>
        <child link="$(arg robot_name)/ee_gripper_link"/>
      </joint>

      <link name="$(arg robot_name)/ee_gripper_link">
        <inertial>
          <mass value="0.001" />
          <inertia ixx="0.001" iyy="0.001" izz="0.001" ixy="0" ixz="0" iyz="0" />
        </inertial>
      </link>

    </xacro:if>

  </xacro:if>

  <!-- <xacro:if value="${urdf_loc != ''}">
    <xacro:include filename="${urdf_loc}"/>
  </xacro:if> -->

</robot>
