<sdf version='1.7'>
  <world name='default'>
    <light name='sun' type='directional'>
      <cast_shadows>1</cast_shadows>
      <pose>0 0 10 0 -0 0</pose>
      <diffuse>0.8 0.8 0.8 1</diffuse>
      <specular>0.2 0.2 0.2 1</specular>
      <attenuation>
        <range>1000</range>
        <constant>0.9</constant>
        <linear>0.01</linear>
        <quadratic>0.001</quadratic>
      </attenuation>
      <direction>-0.5 0.1 -0.9</direction>
      <spot>
        <inner_angle>0</inner_angle>
        <outer_angle>0</outer_angle>
        <falloff>0</falloff>
      </spot>
    </light>
    <model name='ground_plane'>
      <static>1</static>
      <link name='link'>
        <collision name='collision'>
          <geometry>
            <plane>
              <normal>0 0 1</normal>
              <size>100 100</size>
            </plane>
          </geometry>
          <surface>
            <contact>
              <collide_bitmask>65535</collide_bitmask>
              <ode/>
            </contact>
            <friction>
              <ode>
                <mu>100</mu>
                <mu2>50</mu2>
              </ode>
              <torsional>
                <ode/>
              </torsional>
            </friction>
            <bounce/>
          </surface>
          <max_contacts>10</max_contacts>
        </collision>
        <visual name='visual'>
          <cast_shadows>0</cast_shadows>
          <geometry>
            <plane>
              <normal>0 0 1</normal>
              <size>100 100</size>
            </plane>
          </geometry>
          <material>
            <script>
              <uri>file://media/materials/scripts/gazebo.material</uri>
              <name>Gazebo/Grey</name>
            </script>
          </material>
        </visual>
        <self_collide>0</self_collide>
        <enable_wind>0</enable_wind>
        <kinematic>0</kinematic>
      </link>
    </model>
    <gravity>0 0 -9.8</gravity>
    <magnetic_field>6e-06 2.3e-05 -4.2e-05</magnetic_field>
    <atmosphere type='adiabatic'/>
    <physics type='ode'>
      <max_step_size>0.001</max_step_size>
      <real_time_factor>1</real_time_factor>
      <real_time_update_rate>1000</real_time_update_rate>
    </physics>
    <scene>
      <ambient>0.4 0.4 0.4 1</ambient>
      <background>0.7 0.7 0.7 1</background>
      <shadows>1</shadows>
    </scene>
    <wind/>
    <spherical_coordinates>
      <surface_model>EARTH_WGS84</surface_model>
      <latitude_deg>0</latitude_deg>
      <longitude_deg>0</longitude_deg>
      <elevation>0</elevation>
      <heading_deg>0</heading_deg>
    </spherical_coordinates>
    <model name='room-with-slant'>
      <pose>2.33656 -1.76354 0 0 -0 0</pose>
      <link name='Wall_0'>
        <collision name='Wall_0_Collision'>
          <geometry>
            <box>
              <size>0.5 0.15 2.5</size>
            </box>
          </geometry>
          <pose>0 0 1.25 0 -0 0</pose>
          <max_contacts>10</max_contacts>
          <surface>
            <contact>
              <ode/>
            </contact>
            <bounce/>
            <friction>
              <torsional>
                <ode/>
              </torsional>
              <ode/>
            </friction>
          </surface>
        </collision>
        <visual name='Wall_0_Visual'>
          <pose>0 0 1.25 0 -0 0</pose>
          <geometry>
            <box>
              <size>0.5 0.15 2.5</size>
            </box>
          </geometry>
          <material>
            <script>
              <uri>file://media/materials/scripts/gazebo.material</uri>
              <name>Gazebo/Bricks</name>
            </script>
            <ambient>1 1 1 1</ambient>
          </material>
          <meta>
            <layer>0</layer>
          </meta>
        </visual>
        <pose>-5.73263 0.615254 0 0 -0 -1.5708</pose>
        <self_collide>0</self_collide>
        <enable_wind>0</enable_wind>
        <kinematic>0</kinematic>
      </link>
      <link name='Wall_1'>
        <collision name='Wall_1_Collision'>
          <geometry>
            <box>
              <size>3.25 0.15 2.5</size>
            </box>
          </geometry>
          <pose>0 0 1.25 0 -0 0</pose>
          <max_contacts>10</max_contacts>
          <surface>
            <contact>
              <ode/>
            </contact>
            <bounce/>
            <friction>
              <torsional>
                <ode/>
              </torsional>
              <ode/>
            </friction>
          </surface>
        </collision>
        <visual name='Wall_1_Visual'>
          <pose>0 0 1.25 0 -0 0</pose>
          <geometry>
            <box>
              <size>3.25 0.15 2.5</size>
            </box>
          </geometry>
          <material>
            <script>
              <uri>file://media/materials/scripts/gazebo.material</uri>
              <name>Gazebo/Bricks</name>
            </script>
            <ambient>1 1 1 1</ambient>
          </material>
          <meta>
            <layer>0</layer>
          </meta>
        </visual>
        <pose>-4.18263 0.440254 0 0 -0 0</pose>
        <self_collide>0</self_collide>
        <enable_wind>0</enable_wind>
        <kinematic>0</kinematic>
      </link>
      <link name='Wall_2'>
        <collision name='Wall_2_Collision'>
          <geometry>
            <box>
              <size>3 0.15 2.5</size>
            </box>
          </geometry>
          <pose>0 0 1.25 0 -0 0</pose>
          <max_contacts>10</max_contacts>
          <surface>
            <contact>
              <ode/>
            </contact>
            <bounce/>
            <friction>
              <torsional>
                <ode/>
              </torsional>
              <ode/>
            </friction>
          </surface>
        </collision>
        <visual name='Wall_2_Visual'>
          <pose>0 0 1.25 0 -0 0</pose>
          <geometry>
            <box>
              <size>3 0.15 2.5</size>
            </box>
          </geometry>
          <material>
            <script>
              <uri>file://media/materials/scripts/gazebo.material</uri>
              <name>Gazebo/Bricks</name>
            </script>
            <ambient>1 1 1 1</ambient>
          </material>
          <meta>
            <layer>0</layer>
          </meta>
        </visual>
        <pose>-1.625 -0.567373 0 0 -0 -0.785398</pose>
        <self_collide>0</self_collide>
        <enable_wind>0</enable_wind>
        <kinematic>0</kinematic>
      </link>
      <link name='Wall_3'>
        <collision name='Wall_3_Collision'>
          <geometry>
            <box>
              <size>3 0.15 2.5</size>
            </box>
          </geometry>
          <pose>0 0 1.25 0 -0 0</pose>
          <max_contacts>10</max_contacts>
          <surface>
            <contact>
              <ode/>
            </contact>
            <bounce/>
            <friction>
              <torsional>
                <ode/>
              </torsional>
              <ode/>
            </friction>
          </surface>
        </collision>
        <visual name='Wall_3_Visual'>
          <pose>0 0 1.25 0 -0 0</pose>
          <geometry>
            <box>
              <size>3 0.15 2.5</size>
            </box>
          </geometry>
          <material>
            <script>
              <uri>file://media/materials/scripts/gazebo.material</uri>
              <name>Gazebo/Bricks</name>
            </script>
            <ambient>1 1 1 1</ambient>
          </material>
          <meta>
            <layer>0</layer>
          </meta>
        </visual>
        <pose>-0.617373 -3 0 0 -0 -1.5708</pose>
        <self_collide>0</self_collide>
        <enable_wind>0</enable_wind>
        <kinematic>0</kinematic>
      </link>
      <link name='Wall_4'>
        <collision name='Wall_4_Collision'>
          <geometry>
            <box>
              <size>6.5 0.15 2.5</size>
            </box>
          </geometry>
          <pose>0 0 1.25 0 -0 0</pose>
          <max_contacts>10</max_contacts>
          <surface>
            <contact>
              <ode/>
            </contact>
            <bounce/>
            <friction>
              <torsional>
                <ode/>
              </torsional>
              <ode/>
            </friction>
          </surface>
        </collision>
        <visual name='Wall_4_Visual'>
          <pose>0 0 1.25 0 -0 0</pose>
          <geometry>
            <box>
              <size>6.5 0.15 2.5</size>
            </box>
          </geometry>
          <material>
            <script>
              <uri>file://media/materials/scripts/gazebo.material</uri>
              <name>Gazebo/Bricks</name>
            </script>
            <ambient>1 1 1 1</ambient>
          </material>
          <meta>
            <layer>0</layer>
          </meta>
        </visual>
        <pose>2.55763 -4.425 0 0 -0 0</pose>
        <self_collide>0</self_collide>
        <enable_wind>0</enable_wind>
        <kinematic>0</kinematic>
      </link>
      <link name='Wall_5'>
        <collision name='Wall_5_Collision'>
          <geometry>
            <box>
              <size>9 0.15 2.5</size>
            </box>
          </geometry>
          <pose>0 0 1.25 0 -0 0</pose>
          <max_contacts>10</max_contacts>
          <surface>
            <contact>
              <ode/>
            </contact>
            <bounce/>
            <friction>
              <torsional>
                <ode/>
              </torsional>
              <ode/>
            </friction>
          </surface>
        </collision>
        <visual name='Wall_5_Visual'>
          <pose>0 0 1.25 0 -0 0</pose>
          <geometry>
            <box>
              <size>9 0.15 2.5</size>
            </box>
          </geometry>
          <material>
            <script>
              <uri>file://media/materials/scripts/gazebo.material</uri>
              <name>Gazebo/Bricks</name>
            </script>
            <ambient>1 1 1 1</ambient>
          </material>
          <meta>
            <layer>0</layer>
          </meta>
        </visual>
        <pose>5.73263 0 0 0 -0 1.5708</pose>
        <self_collide>0</self_collide>
        <enable_wind>0</enable_wind>
        <kinematic>0</kinematic>
      </link>
      <link name='Wall_6'>
        <collision name='Wall_6_Collision'>
          <geometry>
            <box>
              <size>11.5 0.15 2.5</size>
            </box>
          </geometry>
          <pose>0 0 1.25 0 -0 0</pose>
          <max_contacts>10</max_contacts>
          <surface>
            <contact>
              <ode/>
            </contact>
            <bounce/>
            <friction>
              <torsional>
                <ode/>
              </torsional>
              <ode/>
            </friction>
          </surface>
        </collision>
        <visual name='Wall_6_Visual'>
          <pose>0 0 1.25 0 -0 0</pose>
          <geometry>
            <box>
              <size>11.5 0.15 2.5</size>
            </box>
          </geometry>
          <material>
            <script>
              <uri>file://media/materials/scripts/gazebo.material</uri>
              <name>Gazebo/Bricks</name>
            </script>
            <ambient>1 1 1 1</ambient>
          </material>
          <meta>
            <layer>0</layer>
          </meta>
        </visual>
        <pose>0.057627 4.425 0 0 -0 3.14159</pose>
        <self_collide>0</self_collide>
        <enable_wind>0</enable_wind>
        <kinematic>0</kinematic>
      </link>
      <link name='Wall_7'>
        <collision name='Wall_7_Collision'>
          <geometry>
            <box>
              <size>0.25 0.15 2.5</size>
            </box>
          </geometry>
          <pose>0 0 1.25 0 -0 0</pose>
          <max_contacts>10</max_contacts>
          <surface>
            <contact>
              <ode/>
            </contact>
            <bounce/>
            <friction>
              <torsional>
                <ode/>
              </torsional>
              <ode/>
            </friction>
          </surface>
        </collision>
        <visual name='Wall_7_Visual'>
          <pose>0 0 1.25 0 -0 0</pose>
          <geometry>
            <box>
              <size>0.25 0.15 2.5</size>
            </box>
          </geometry>
          <material>
            <script>
              <uri>file://media/materials/scripts/gazebo.material</uri>
              <name>Gazebo/Grey</name>
            </script>
            <ambient>1 1 1 1</ambient>
          </material>
          <meta>
            <layer>0</layer>
          </meta>
        </visual>
        <pose>-5.66737 4.425 0 0 -0 3.14159</pose>
        <self_collide>0</self_collide>
        <enable_wind>0</enable_wind>
        <kinematic>0</kinematic>
      </link>
      <link name='Wall_8'>
        <collision name='Wall_8_Collision'>
          <geometry>
            <box>
              <size>2.75 0.15 2.5</size>
            </box>
          </geometry>
          <pose>0 0 1.25 0 -0 0</pose>
          <max_contacts>10</max_contacts>
          <surface>
            <contact>
              <ode/>
            </contact>
            <bounce/>
            <friction>
              <torsional>
                <ode/>
              </torsional>
              <ode/>
            </friction>
          </surface>
        </collision>
        <visual name='Wall_8_Visual'>
          <pose>0 0 1.25 0 -0 0</pose>
          <geometry>
            <box>
              <size>2.75 0.15 2.5</size>
            </box>
          </geometry>
          <material>
            <script>
              <uri>file://media/materials/scripts/gazebo.material</uri>
              <name>Gazebo/Bricks</name>
            </script>
            <ambient>1 1 1 1</ambient>
          </material>
          <meta>
            <layer>0</layer>
          </meta>
        </visual>
        <pose>-5.71737 3.125 0 0 -0 -1.5708</pose>
        <self_collide>0</self_collide>
        <enable_wind>0</enable_wind>
        <kinematic>0</kinematic>
      </link>
      <static>1</static>
    </model>
    <model name='door-model'>
      <link name='door'>
        <inertial>
          <mass>20</mass>
          <inertia>
            <ixx>4.53808</ixx>
            <ixy>0</ixy>
            <ixz>0</ixz>
            <iyy>4.54003</iyy>
            <iyz>0</iyz>
            <izz>0.0512722</izz>
          </inertia>
          <pose>0 0 0 0 -0 0</pose>
        </inertial>
        <pose>0 0 0 0 -0 0</pose>
        <gravity>0</gravity>
        <self_collide>0</self_collide>
        <kinematic>0</kinematic>
        <enable_wind>0</enable_wind>
        <visual name='visual'>
          <pose>0 0 0 0 -0 0</pose>
          <geometry>
            <mesh>
              <uri>/home/hwixley/Documents/Year3/SDP/GitRepo/SDP-DrPhil-Add-Door-Gazebo/ros-workspace/src/dr-phil/models/door-model/./FinalDoorHopefully-HHandles.stl</uri>
              <scale>0.001 0.001 0.001</scale>
            </mesh>
          </geometry>
          <material>
            <lighting>1</lighting>
            <script>
              <uri>file://media/materials/scripts/gazebo.material</uri>
              <name>Gazebo/Grey</name>
            </script>
            <shader type='pixel'>
              <normal_map>__default__</normal_map>
            </shader>
            <ambient>0.3 0.3 0.3 1</ambient>
            <diffuse>0.7 0.7 0.7 1</diffuse>
            <specular>0.01 0.01 0.01 1</specular>
            <emissive>0 0 0 1</emissive>
          </material>
          <transparency>0</transparency>
          <cast_shadows>1</cast_shadows>
        </visual>
        <collision name='collision'>
          <laser_retro>0</laser_retro>
          <max_contacts>10</max_contacts>
          <pose>0 0 0 0 -0 0</pose>
          <geometry>
            <mesh>
              <uri>/home/hwixley/Documents/Year3/SDP/GitRepo/SDP-DrPhil-Add-Door-Gazebo/ros-workspace/src/dr-phil/models/door-model/./FinalDoorHopefully-HHandles.stl</uri>
              <scale>0.001 0.001 0.001</scale>
            </mesh>
          </geometry>
          <surface>
            <friction>
              <ode>
                <mu>1</mu>
                <mu2>1</mu2>
                <fdir1>0 0 0</fdir1>
                <slip1>0</slip1>
                <slip2>0</slip2>
              </ode>
              <torsional>
                <coefficient>1</coefficient>
                <patch_radius>0</patch_radius>
                <surface_radius>0</surface_radius>
                <use_patch_radius>1</use_patch_radius>
                <ode>
                  <slip>0</slip>
                </ode>
              </torsional>
            </friction>
            <bounce>
              <restitution_coefficient>0</restitution_coefficient>
              <threshold>1e+06</threshold>
            </bounce>
            <contact>
              <collide_without_contact>0</collide_without_contact>
              <collide_without_contact_bitmask>1</collide_without_contact_bitmask>
              <collide_bitmask>1</collide_bitmask>
              <ode>
                <soft_cfm>0</soft_cfm>
                <soft_erp>0.2</soft_erp>
                <kp>1e+13</kp>
                <kd>1</kd>
                <max_vel>0.01</max_vel>
                <min_depth>0</min_depth>
              </ode>
              <bullet>
                <split_impulse>1</split_impulse>
                <split_impulse_penetration_threshold>-0.01</split_impulse_penetration_threshold>
                <soft_cfm>0</soft_cfm>
                <soft_erp>0.2</soft_erp>
                <kp>1e+13</kp>
                <kd>1</kd>
              </bullet>
            </contact>
          </surface>
        </collision>
      </link>
      <link name='pole'>
        <inertial>
          <mass>100</mass>
          <inertia>
            <ixx>0.001</ixx>
            <ixy>0.001</ixy>
            <ixz>0.001</ixz>
            <iyy>0.001</iyy>
            <iyz>0.001</iyz>
            <izz>0.001</izz>
          </inertia>
          <pose>0 0 0 0 -0 0</pose>
        </inertial>
        <pose>-0.02632 0 0.308096 0 -0 0</pose>
        <gravity>0</gravity>
        <self_collide>0</self_collide>
        <kinematic>1</kinematic>
        <enable_wind>0</enable_wind>
        <visual name='visual'>
          <pose>0 0 0 0 -0 0</pose>
          <geometry>
            <box>
              <size>0.048276 0.0462 0.625074</size>
            </box>
          </geometry>
          <material>
            <lighting>1</lighting>
            <script>
              <uri>file://media/materials/scripts/gazebo.material</uri>
              <name>Gazebo/Grey</name>
            </script>
            <shader type='pixel'>
              <normal_map>__default__</normal_map>
            </shader>
            <ambient>0.3 0.3 0.3 1</ambient>
            <diffuse>0.7 0.7 0.7 1</diffuse>
            <specular>0.01 0.01 0.01 1</specular>
            <emissive>0 0 0 1</emissive>
          </material>
          <transparency>0</transparency>
          <cast_shadows>1</cast_shadows>
        </visual>
        <collision name='collision'>
          <laser_retro>0</laser_retro>
          <max_contacts>10</max_contacts>
          <pose>0 0 0 0 -0 0</pose>
          <geometry>
            <box>
              <size>0.048 0.046201 0.625074</size>
            </box>
          </geometry>
          <surface>
            <friction>
              <ode>
                <mu>1</mu>
                <mu2>1</mu2>
                <fdir1>0 0 0</fdir1>
                <slip1>0</slip1>
                <slip2>0</slip2>
              </ode>
              <torsional>
                <coefficient>1</coefficient>
                <patch_radius>0</patch_radius>
                <surface_radius>0</surface_radius>
                <use_patch_radius>1</use_patch_radius>
                <ode>
                  <slip>0</slip>
                </ode>
              </torsional>
            </friction>
            <bounce>
              <restitution_coefficient>0</restitution_coefficient>
              <threshold>1e+06</threshold>
            </bounce>
            <contact>
              <collide_without_contact>0</collide_without_contact>
              <collide_without_contact_bitmask>1</collide_without_contact_bitmask>
              <collide_bitmask>1</collide_bitmask>
              <ode>
                <soft_cfm>0</soft_cfm>
                <soft_erp>0.2</soft_erp>
                <kp>1e+13</kp>
                <kd>1</kd>
                <max_vel>0.01</max_vel>
                <min_depth>0</min_depth>
              </ode>
              <bullet>
                <split_impulse>1</split_impulse>
                <split_impulse_penetration_threshold>-0.01</split_impulse_penetration_threshold>
                <soft_cfm>0</soft_cfm>
                <soft_erp>0.2</soft_erp>
                <kp>1e+13</kp>
                <kd>1</kd>
              </bullet>
            </contact>
          </surface>
        </collision>
      </link>
      <joint name='hinge' type='revolute'>
        <parent>pole</parent>
        <child>door</child>
        <pose>0 0 0.3 0 -0 0</pose>
        <axis>
          <xyz>0 0 1</xyz>
          <limit>
            <lower>-1.74533</lower>
            <upper>1.74533</upper>
            <effort>3900</effort>
            <velocity>0.62</velocity>
          </limit>
          <dynamics>
            <spring_reference>0</spring_reference>
            <spring_stiffness>0</spring_stiffness>
            <damping>0.1</damping>
            <friction>0.1</friction>
          </dynamics>
        </axis>
        <physics>
          <ode>
            <limit>
              <cfm>0</cfm>
              <erp>0.2</erp>
            </limit>
            <suspension>
              <cfm>0</cfm>
              <erp>0.2</erp>
            </suspension>
          </ode>
        </physics>
      </joint>
      <static>0</static>
      <allow_auto_disable>1</allow_auto_disable>
      <pose>-3.71455 -0.469398 0 0 -0 0</pose>
    </model>
    <state world_name='default'>
      <sim_time>235 777000000</sim_time>
      <real_time>241 200884857</real_time>
      <wall_time>1612716786 244505893</wall_time>
      <iterations>235777</iterations>
      <model name='bookshelf'>
        <pose>1.66514 7.57511 -0 0 -0 0</pose>
        <scale>1 1 1</scale>
        <link name='link'>
          <pose>1.66514 7.57511 -0 0 -0 0</pose>
          <velocity>0 0 0 0 -0 0</velocity>
          <acceleration>0 0 0 0 -0 0</acceleration>
          <wrench>0 0 0 0 -0 0</wrench>
        </link>
      </model>
      <model name='cafe_table'>
        <pose>2.4295 1.59973 0.182259 0 -0 0</pose>
        <scale>1 1 1</scale>
        <link name='link'>
          <pose>2.4295 1.59973 0.182259 0 -0 0</pose>
          <velocity>0 0 0 0 -0 0</velocity>
          <acceleration>0 0 0 0 -0 0</acceleration>
          <wrench>0 0 0 0 -0 0</wrench>
        </link>
      </model>
      <model name='door-model'>
        <pose>-7.68566 4.33903 0 0 -0 1.57439</pose>
        <scale>1 1 1</scale>
        <link name='door'>
          <pose>-7.68566 4.33903 0 0 -0 1.57439</pose>
          <velocity>-0 0 0 0 -0 0</velocity>
          <acceleration>0 0 0 0 -0 0</acceleration>
          <wrench>0 0 0 0 -0 0</wrench>
        </link>
        <link name='pole'>
          <pose>-7.68556 4.31271 0.308096 0 -0 1.57439</pose>
          <velocity>0 0 0 0 -0 0</velocity>
          <acceleration>0 0 0 0 -0 0</acceleration>
          <wrench>0 0 0 0 -0 0</wrench>
        </link>
      </model>
      <model name='dr-phil'>
        <pose>-1.99961 -0.49488 -0.001007 -4e-06 0.003151 0.031738</pose>
        <scale>1 1 1</scale>
        <link name='base_footprint'>
          <pose>-1.99961 -0.49488 -0.001007 -4e-06 0.003151 0.031738</pose>
          <velocity>-1.6e-05 3.5e-05 -3.4e-05 4.1e-05 -0.000342 0.000214</velocity>
          <acceleration>-0.028197 0.000825 -0.205784 -0.041806 -0.010557 -0.009726</acceleration>
          <wrench>-0.061185 0.001791 -0.446528 0 -0 0</wrench>
        </link>
        <link name='px100/forearm_link'>
          <pose>-1.88499 -0.490955 0.223435 -2.3e-05 1.28986 0.034446</pose>
          <velocity>0.001694 6.8e-05 -0.004201 -4.7e-05 0.015474 6.6e-05</velocity>
          <acceleration>1.33912 0.049641 -9.37382 0.199906 0.096541 -2.81482</acceleration>
          <wrench>0.097833 0.003627 -0.684833 0 -0 0</wrench>
        </link>
        <link name='px100/gripper_link'>
          <pose>-1.85728 -0.49 0.127356 -2.4e-05 1.28668 0.034446</pose>
          <velocity>9.7e-05 5.5e-05 -0.004726 -3.1e-05 0.013602 8.1e-05</velocity>
          <acceleration>-1.18106 0.009243 -10.4942 3.06549 0.148907 2.94217</acceleration>
          <wrench>-0.126525 0.00099 -1.12423 0 -0 0</wrench>
        </link>
        <link name='px100/gripper_prop_link'>
          <pose>-1.83809 -0.489339 0.061602 -0.000515 1.28668 0.034446</pose>
          <velocity>-0.000807 5.4e-05 -0.004984 -3.8e-05 0.013682 8.2e-05</velocity>
          <acceleration>-1.6786 0.008421 -10.3696 -2.05728 -1.24069 -0.062621</acceleration>
          <wrench>-0.007285 3.7e-05 -0.045004 0 -0 0</wrench>
        </link>
        <link name='px100/left_finger_link'>
          <pose>-1.83416 -0.460831 0.044807 -6e-06 1.28681 0.03446</pose>
          <velocity>-0.000926 0.000155 -0.005816 -0.001983 -0.020826 -0.002385</velocity>
          <acceleration>-1.28762 0.166429 -11.8127 -2.68358 -0.635055 1.93521</acceleration>
          <wrench>-0.020919 0.002704 -0.191909 0 -0 0</wrench>
        </link>
        <link name='px100/right_finger_link'>
          <pose>-1.83219 -0.517892 0.044807 -7.4e-05 1.2868 0.034472</pose>
          <velocity>-0.001007 -0.000134 -0.005776 0.006503 -0.019007 -0.016287</velocity>
          <acceleration>-1.51969 -0.356066 -11.7482 3.01231 -0.378401 -0.434766</acceleration>
          <wrench>-0.024689 -0.005785 -0.190861 0 -0 0</wrench>
        </link>
        <link name='px100/shoulder_link'>
          <pose>-1.98898 -0.494542 0.201811 -1e-06 0.003143 0.034474</pose>
          <velocity>0.000584 5.6e-05 -0.000227 -0.000966 0.032374 -0.000457</velocity>
          <acceleration>3.04741 0.111309 -0.599931 -0.392149 0.453073 -0.662234</acceleration>
          <wrench>0.221203 0.00808 -0.043547 0 -0 0</wrench>
        </link>
        <link name='px100/upper_arm_link'>
          <pose>-1.98885 -0.494537 0.244064 -2.5e-05 1.43009 0.034448</pose>
          <velocity>0.001384 6.6e-05 -0.00174 -0.000359 0.02298 -5e-05</velocity>
          <acceleration>2.67503 0.040368 -7.81072 -0.177353 0.907887 -3.02073</acceleration>
          <wrench>0.221822 0.003347 -0.647688 0 -0 0</wrench>
        </link>
        <link name='wheel_left_link'>
          <pose>-2.00408 -0.350952 0.031993 -1.57015 -0.121923 0.03166</pose>
          <velocity>-7.3e-05 4.2e-05 0.000313 -0.000625 -0.001014 0.000135</velocity>
          <acceleration>-0.058911 0.024657 0.454188 -0.867914 -0.066975 -0.148066</acceleration>
          <wrench>-0.001679 0.000703 0.012944 0 -0 0</wrench>
        </link>
        <link name='wheel_right_link'>
          <pose>-1.99494 -0.638807 0.031994 -1.57017 0.156193 0.031826</pose>
          <velocity>1.6e-05 6e-05 0.000273 -0.001092 -0.000773 0.000255</velocity>
          <acceleration>-0.009103 0.047826 0.406304 -1.5011 -1.22444 0.155313</acceleration>
          <wrench>-0.000259 0.001363 0.011579 0 -0 0</wrench>
        </link>
      </model>
      <model name='ground_plane'>
        <pose>0 0 0 0 -0 0</pose>
        <scale>1 1 1</scale>
        <link name='link'>
          <pose>0 0 0 0 -0 0</pose>
          <velocity>0 0 0 0 -0 0</velocity>
          <acceleration>0 0 0 0 -0 0</acceleration>
          <wrench>0 0 0 0 -0 0</wrench>
        </link>
      </model>
      <model name='person_standing'>
        <pose>2.17439 0.772639 -1e-06 -1e-06 1e-06 1.94365</pose>
        <scale>1 1 1</scale>
        <link name='link'>
          <pose>2.17439 0.772639 -1e-06 -1e-06 1e-06 1.94365</pose>
          <velocity>0 0 0 0 -0 0</velocity>
          <acceleration>-1.64912 1.09222 -1.47479 2.05856 -1.36071 3.09803</acceleration>
          <wrench>-131.929 87.3776 -117.983 0 -0 0</wrench>
        </link>
      </model>
      <model name='person_walking'>
        <pose>-4.01039 6.66178 -0 -0 1e-06 0.453325</pose>
        <scale>1 1 1</scale>
        <link name='link'>
          <pose>-4.01039 6.66178 -0 -0 1e-06 0.453325</pose>
          <velocity>0 0 0 0 -0 0</velocity>
          <acceleration>1.14493 0.56116 -0.493033 -0.65419 1.20826 0.00015</acceleration>
          <wrench>91.5946 44.8928 -39.4427 0 -0 0</wrench>
        </link>
      </model>
      <model name='room-with-slant'>
        <pose>-2.03347 3.34781 0 0 -0 0</pose>
        <scale>1 1 1</scale>
        <link name='Wall_0'>
          <pose>-7.7661 3.96307 0 0 0 -1.5708</pose>
          <velocity>0 0 0 0 -0 0</velocity>
          <acceleration>0 0 0 0 -0 0</acceleration>
          <wrench>0 0 0 0 -0 0</wrench>
        </link>
        <link name='Wall_1'>
          <pose>-6.2161 3.78807 0 0 -0 0</pose>
          <velocity>0 0 0 0 -0 0</velocity>
          <acceleration>0 0 0 0 -0 0</acceleration>
          <wrench>0 0 0 0 -0 0</wrench>
        </link>
        <link name='Wall_2'>
          <pose>-3.65847 2.78045 0 0 0 -0.785398</pose>
          <velocity>0 0 0 0 -0 0</velocity>
          <acceleration>0 0 0 0 -0 0</acceleration>
          <wrench>0 0 0 0 -0 0</wrench>
        </link>
        <link name='Wall_3'>
          <pose>-2.65084 0.347817 0 0 0 -1.5708</pose>
          <velocity>0 0 0 0 -0 0</velocity>
          <acceleration>0 0 0 0 -0 0</acceleration>
          <wrench>0 0 0 0 -0 0</wrench>
        </link>
        <link name='Wall_4'>
          <pose>0.524157 -1.07718 0 0 -0 0</pose>
          <velocity>0 0 0 0 -0 0</velocity>
          <acceleration>0 0 0 0 -0 0</acceleration>
          <wrench>0 0 0 0 -0 0</wrench>
        </link>
        <link name='Wall_5'>
          <pose>3.69916 3.34782 0 0 -0 1.5708</pose>
          <velocity>0 0 0 0 -0 0</velocity>
          <acceleration>0 0 0 0 -0 0</acceleration>
          <wrench>0 0 0 0 -0 0</wrench>
        </link>
        <link name='Wall_6'>
          <pose>-1.97584 7.77282 0 0 -0 3.14159</pose>
          <velocity>0 0 0 0 -0 0</velocity>
          <acceleration>0 0 0 0 -0 0</acceleration>
          <wrench>0 0 0 0 -0 0</wrench>
        </link>
        <link name='Wall_7'>
          <pose>-7.70084 7.77282 0 0 -0 3.14159</pose>
          <velocity>0 0 0 0 -0 0</velocity>
          <acceleration>0 0 0 0 -0 0</acceleration>
          <wrench>0 0 0 0 -0 0</wrench>
        </link>
        <link name='Wall_8'>
          <pose>-7.75084 6.47282 0 0 0 -1.5708</pose>
          <velocity>0 0 0 0 -0 0</velocity>
          <acceleration>0 0 0 0 -0 0</acceleration>
          <wrench>0 0 0 0 -0 0</wrench>
        </link>
      </model>
      <light name='sun'>
        <pose>0 0 10 0 -0 0</pose>
      </light>
    </state>
    <model name='bookshelf'>
      <static>1</static>
      <link name='link'>
        <inertial>
          <mass>1</mass>
        </inertial>
        <collision name='back'>
          <pose>0 0.005 0.6 0 -0 0</pose>
          <geometry>
            <box>
              <size>0.9 0.01 1.2</size>
            </box>
          </geometry>
          <max_contacts>10</max_contacts>
          <surface>
            <contact>
              <ode/>
            </contact>
            <bounce/>
            <friction>
              <torsional>
                <ode/>
              </torsional>
              <ode/>
            </friction>
          </surface>
        </collision>
        <visual name='visual1'>
          <pose>0 0.005 0.6 0 -0 0</pose>
          <geometry>
            <box>
              <size>0.9 0.01 1.2</size>
            </box>
          </geometry>
          <material>
            <script>
              <uri>file://media/materials/scripts/gazebo.material</uri>
              <name>Gazebo/Wood</name>
            </script>
          </material>
        </visual>
        <collision name='left_side'>
          <pose>0.45 -0.195 0.6 0 -0 0</pose>
          <geometry>
            <box>
              <size>0.02 0.4 1.2</size>
            </box>
          </geometry>
          <max_contacts>10</max_contacts>
          <surface>
            <contact>
              <ode/>
            </contact>
            <bounce/>
            <friction>
              <torsional>
                <ode/>
              </torsional>
              <ode/>
            </friction>
          </surface>
        </collision>
        <visual name='visual2'>
          <pose>0.45 -0.195 0.6 0 -0 0</pose>
          <geometry>
            <box>
              <size>0.02 0.4 1.2</size>
            </box>
          </geometry>
          <material>
            <script>
              <uri>file://media/materials/scripts/gazebo.material</uri>
              <name>Gazebo/Wood</name>
            </script>
          </material>
        </visual>
        <collision name='right_side'>
          <pose>-0.45 -0.195 0.6 0 -0 0</pose>
          <geometry>
            <box>
              <size>0.02 0.4 1.2</size>
            </box>
          </geometry>
          <max_contacts>10</max_contacts>
          <surface>
            <contact>
              <ode/>
            </contact>
            <bounce/>
            <friction>
              <torsional>
                <ode/>
              </torsional>
              <ode/>
            </friction>
          </surface>
        </collision>
        <visual name='visual3'>
          <pose>-0.45 -0.195 0.6 0 -0 0</pose>
          <geometry>
            <box>
              <size>0.02 0.4 1.2</size>
            </box>
          </geometry>
          <material>
            <script>
              <uri>file://media/materials/scripts/gazebo.material</uri>
              <name>Gazebo/Wood</name>
            </script>
          </material>
        </visual>
        <collision name='bottom'>
          <pose>0 -0.195 0.03 0 -0 0</pose>
          <geometry>
            <box>
              <size>0.88 0.4 0.06</size>
            </box>
          </geometry>
          <max_contacts>10</max_contacts>
          <surface>
            <contact>
              <ode/>
            </contact>
            <bounce/>
            <friction>
              <torsional>
                <ode/>
              </torsional>
              <ode/>
            </friction>
          </surface>
        </collision>
        <visual name='visual4'>
          <pose>0 -0.195 0.03 0 -0 0</pose>
          <geometry>
            <box>
              <size>0.88 0.4 0.06</size>
            </box>
          </geometry>
          <material>
            <script>
              <uri>file://media/materials/scripts/gazebo.material</uri>
              <name>Gazebo/Wood</name>
            </script>
          </material>
        </visual>
        <collision name='top'>
          <pose>0 -0.195 1.19 0 -0 0</pose>
          <geometry>
            <box>
              <size>0.88 0.4 0.02</size>
            </box>
          </geometry>
          <max_contacts>10</max_contacts>
          <surface>
            <contact>
              <ode/>
            </contact>
            <bounce/>
            <friction>
              <torsional>
                <ode/>
              </torsional>
              <ode/>
            </friction>
          </surface>
        </collision>
        <visual name='visual5'>
          <pose>0 -0.195 1.19 0 -0 0</pose>
          <geometry>
            <box>
              <size>0.88 0.4 0.02</size>
            </box>
          </geometry>
          <material>
            <script>
              <uri>file://media/materials/scripts/gazebo.material</uri>
              <name>Gazebo/Wood</name>
            </script>
          </material>
        </visual>
        <collision name='low_shelf'>
          <pose>0 -0.195 0.43 0 -0 0</pose>
          <geometry>
            <box>
              <size>0.88 0.4 0.02</size>
            </box>
          </geometry>
          <max_contacts>10</max_contacts>
          <surface>
            <contact>
              <ode/>
            </contact>
            <bounce/>
            <friction>
              <torsional>
                <ode/>
              </torsional>
              <ode/>
            </friction>
          </surface>
        </collision>
        <visual name='visual6'>
          <pose>0 -0.195 0.43 0 -0 0</pose>
          <geometry>
            <box>
              <size>0.88 0.4 0.02</size>
            </box>
          </geometry>
          <material>
            <script>
              <uri>file://media/materials/scripts/gazebo.material</uri>
              <name>Gazebo/Wood</name>
            </script>
          </material>
        </visual>
        <collision name='high_shelf'>
          <pose>0 -0.195 0.8 0 -0 0</pose>
          <geometry>
            <box>
              <size>0.88 0.4 0.02</size>
            </box>
          </geometry>
          <max_contacts>10</max_contacts>
          <surface>
            <contact>
              <ode/>
            </contact>
            <bounce/>
            <friction>
              <torsional>
                <ode/>
              </torsional>
              <ode/>
            </friction>
          </surface>
        </collision>
        <visual name='visual7'>
          <pose>0 -0.195 0.8 0 -0 0</pose>
          <geometry>
            <box>
              <size>0.88 0.4 0.02</size>
            </box>
          </geometry>
          <material>
            <script>
              <uri>file://media/materials/scripts/gazebo.material</uri>
              <name>Gazebo/Wood</name>
            </script>
          </material>
        </visual>
        <self_collide>0</self_collide>
        <enable_wind>0</enable_wind>
        <kinematic>0</kinematic>
      </link>
      <pose>5 2.5199 0 0 -0 0</pose>
    </model>
    <model name='cafe_table'>
      <static>1</static>
      <link name='link'>
        <collision name='surface'>
          <pose>0 0 0.755 0 -0 0</pose>
          <geometry>
            <box>
              <size>0.913 0.913 0.04</size>
            </box>
          </geometry>
          <max_contacts>10</max_contacts>
          <surface>
            <contact>
              <ode/>
            </contact>
            <bounce/>
            <friction>
              <torsional>
                <ode/>
              </torsional>
              <ode/>
            </friction>
          </surface>
        </collision>
        <collision name='column'>
          <pose>0 0 0.37 0 -0 0</pose>
          <geometry>
            <box>
              <size>0.042 0.042 0.74</size>
            </box>
          </geometry>
          <max_contacts>10</max_contacts>
          <surface>
            <contact>
              <ode/>
            </contact>
            <bounce/>
            <friction>
              <torsional>
                <ode/>
              </torsional>
              <ode/>
            </friction>
          </surface>
        </collision>
        <collision name='base'>
          <pose>0 0 0.02 0 -0 0</pose>
          <geometry>
            <box>
              <size>0.56 0.56 0.04</size>
            </box>
          </geometry>
          <max_contacts>10</max_contacts>
          <surface>
            <contact>
              <ode/>
            </contact>
            <bounce/>
            <friction>
              <torsional>
                <ode/>
              </torsional>
              <ode/>
            </friction>
          </surface>
        </collision>
        <visual name='visual'>
          <geometry>
            <mesh>
              <uri>model://cafe_table/meshes/cafe_table.dae</uri>
            </mesh>
          </geometry>
        </visual>
        <self_collide>0</self_collide>
        <enable_wind>0</enable_wind>
        <kinematic>0</kinematic>
      </link>
      <pose>4.65778 -0.25167 0 0 -0 0</pose>
    </model>
    <model name='person_standing'>
      <link name='link'>
        <inertial>
          <pose>0 -0.1 0.95 0 -0 0</pose>
          <mass>80</mass>
          <inertia>
            <ixx>24.88</ixx>
            <ixy>0</ixy>
            <ixz>0</ixz>
            <iyy>25.73</iyy>
            <iyz>0</iyz>
            <izz>2.48</izz>
          </inertia>
        </inertial>
        <collision name='bottom'>
          <pose>0 -0.1 0.01 0 -0 0</pose>
          <geometry>
            <box>
              <size>0.5 0.35 0.02</size>
            </box>
          </geometry>
          <max_contacts>10</max_contacts>
          <surface>
            <contact>
              <ode/>
            </contact>
            <bounce/>
            <friction>
              <torsional>
                <ode/>
              </torsional>
              <ode/>
            </friction>
          </surface>
        </collision>
        <collision name='person'>
          <pose>0 0 0.02 0.04 -0 0</pose>
          <geometry>
            <mesh>
              <uri>model://person_standing/meshes/standing.dae</uri>
            </mesh>
          </geometry>
          <max_contacts>10</max_contacts>
          <surface>
            <contact>
              <ode/>
            </contact>
            <bounce/>
            <friction>
              <torsional>
                <ode/>
              </torsional>
              <ode/>
            </friction>
          </surface>
        </collision>
        <visual name='visual'>
          <pose>0 0 0.02 0.04 -0 0</pose>
          <geometry>
            <mesh>
              <uri>model://person_standing/meshes/standing.dae</uri>
            </mesh>
          </geometry>
        </visual>
        <self_collide>0</self_collide>
        <enable_wind>0</enable_wind>
        <kinematic>0</kinematic>
      </link>
      <pose>4.59634 -1.01999 0 0 -0 0</pose>
    </model>
    <model name='person_walking'>
      <link name='link'>
        <inertial>
          <pose>0 0 0.95 0 -0 0</pose>
          <mass>80</mass>
          <inertia>
            <ixx>27.82</ixx>
            <ixy>0</ixy>
            <ixz>0</ixz>
            <iyy>24.88</iyy>
            <iyz>0</iyz>
            <izz>4.57</izz>
          </inertia>
        </inertial>
        <collision name='bottom'>
          <pose>0 0 0.01 0 -0 0</pose>
          <geometry>
            <box>
              <size>0.35 0.75 0.02</size>
            </box>
          </geometry>
          <max_contacts>10</max_contacts>
          <surface>
            <contact>
              <ode/>
            </contact>
            <bounce/>
            <friction>
              <torsional>
                <ode/>
              </torsional>
              <ode/>
            </friction>
          </surface>
        </collision>
        <collision name='person'>
          <pose>0 0 -0.02 0 -0 0</pose>
          <geometry>
            <mesh>
              <uri>model://person_walking/meshes/walking.dae</uri>
            </mesh>
          </geometry>
          <max_contacts>10</max_contacts>
          <surface>
            <contact>
              <ode/>
            </contact>
            <bounce/>
            <friction>
              <torsional>
                <ode/>
              </torsional>
              <ode/>
            </friction>
          </surface>
        </collision>
        <visual name='visual'>
          <pose>0 0 -0.02 0 -0 0</pose>
          <geometry>
            <mesh>
              <uri>model://person_walking/meshes/walking.dae</uri>
            </mesh>
          </geometry>
        </visual>
        <self_collide>0</self_collide>
        <enable_wind>0</enable_wind>
        <kinematic>0</kinematic>
      </link>
      <pose>-0.16538 1.60184 0 0 -0 0</pose>
    </model>
    <gui fullscreen='0'>
      <camera name='user_camera'>
        <pose>-1.65331 4.72591 7.20595 0 0.992974 -3.13636</pose>
        <view_controller>orbit</view_controller>
        <projection_type>perspective</projection_type>
      </camera>
    </gui>
    <model name='dr-phil'>
      <link name='base_footprint'>
        <inertial>
          <pose>-0.057078 0.000163 0.046165 0 -0 0</pose>
          <mass>2.16989</mass>
          <inertia>
            <ixx>0.0214767</ixx>
            <ixy>-4.65024e-05</ixy>
            <ixz>-0.00202619</ixz>
            <iyy>0.0227691</iyy>
            <iyz>-4.65166e-05</iyz>
            <izz>0.0195445</izz>
          </inertia>
        </inertial>
        <collision name='base_footprint_fixed_joint_lump__base_link_collision'>
          <pose>-0.064 0 0.057 0 -0 0</pose>
          <geometry>
            <box>
              <size>0.266 0.266 0.094</size>
            </box>
          </geometry>
          <surface>
            <contact>
              <ode/>
            </contact>
            <friction>
              <ode/>
              <torsional>
                <ode/>
              </torsional>
            </friction>
            <bounce/>
          </surface>
          <max_contacts>10</max_contacts>
        </collision>
        <collision name='base_footprint_fixed_joint_lump__px100/base_arm_collision_1'>
          <pose>0.01 0 0.152 0 -0 1.5708</pose>
          <geometry>
            <mesh>
              <scale>0.001 0.001 0.001</scale>
              <uri>/home/hwixley/Documents/Year3/SDP/GitRepo/SDP-DrPhil-Add-Door-Gazebo/ros-workspace/src/dr-phil/meshes/px100_meshes/px100_1_base.stl</uri>
            </mesh>
          </geometry>
          <max_contacts>10</max_contacts>
          <surface>
            <contact>
              <ode/>
            </contact>
            <bounce/>
            <friction>
              <torsional>
                <ode/>
              </torsional>
              <ode/>
            </friction>
          </surface>
        </collision>
        <collision name='base_footprint_fixed_joint_lump__camera_link_collision_2'>
          <pose>0.078 0 0.107 0 -0 0</pose>
          <geometry>
            <box>
              <size>0.015 0.03 0.027</size>
            </box>
          </geometry>
          <max_contacts>10</max_contacts>
          <surface>
            <contact>
              <ode/>
            </contact>
            <bounce/>
            <friction>
              <torsional>
                <ode/>
              </torsional>
              <ode/>
            </friction>
          </surface>
        </collision>
        <collision name='base_footprint_fixed_joint_lump__caster_back_left_link_collision_3'>
          <pose>-0.177 0.064001 0.005 -1.57 0 0</pose>
          <geometry>
            <box>
              <size>0.03 0.009 0.02</size>
            </box>
          </geometry>
          <surface>
            <contact>
              <ode>
                <kp>1e+06</kp>
                <kd>100</kd>
                <max_vel>1</max_vel>
                <min_depth>0.001</min_depth>
              </ode>
            </contact>
            <friction>
              <ode>
                <mu>0.1</mu>
                <mu2>0.1</mu2>
              </ode>
              <torsional>
                <ode/>
              </torsional>
            </friction>
            <bounce/>
          </surface>
          <max_contacts>10</max_contacts>
        </collision>
        <collision name='base_footprint_fixed_joint_lump__caster_back_right_link_collision_4'>
          <pose>-0.177 -0.063999 0.005 -1.57 0 0</pose>
          <geometry>
            <box>
              <size>0.03 0.009 0.02</size>
            </box>
          </geometry>
          <surface>
            <contact>
              <ode>
                <kp>1e+06</kp>
                <kd>100</kd>
                <max_vel>1</max_vel>
                <min_depth>0.001</min_depth>
              </ode>
            </contact>
            <friction>
              <ode>
                <mu>0.1</mu>
                <mu2>0.1</mu2>
              </ode>
              <torsional>
                <ode/>
              </torsional>
            </friction>
            <bounce/>
          </surface>
          <max_contacts>10</max_contacts>
        </collision>
        <collision name='base_footprint_fixed_joint_lump__base_scan_collision_5'>
          <pose>-0.049 0 0.1255 0 -0 0</pose>
          <geometry>
            <cylinder>
              <length>0.0315</length>
              <radius>0.055</radius>
            </cylinder>
          </geometry>
          <surface>
            <contact>
              <ode/>
            </contact>
            <friction>
              <ode/>
              <torsional>
                <ode/>
              </torsional>
            </friction>
            <bounce/>
          </surface>
          <max_contacts>10</max_contacts>
        </collision>
        <visual name='base_footprint_fixed_joint_lump__base_link_visual'>
          <pose>-0.064 0 0.01 0 -0 0</pose>
          <geometry>
            <mesh>
              <scale>0.001 0.001 0.001</scale>
              <uri>/home/hwixley/Documents/Year3/SDP/GitRepo/SDP-DrPhil-Add-Door-Gazebo/ros-workspace/src/dr-phil/meshes/bases/waffle_pi_base.stl</uri>
            </mesh>
          </geometry>
          <material>
            <script>
              <name>Gazebo/DarkGrey</name>
              <uri>file://media/materials/scripts/gazebo.material</uri>
            </script>
          </material>
        </visual>
        <visual name='base_footprint_fixed_joint_lump__base_link_visual_1'>
          <pose>-0.064 0 0.06 0 -0 0</pose>
          <geometry>
            <mesh>
              <scale>0.001 0.001 0.001</scale>
              <uri>/home/hwixley/Documents/Year3/SDP/GitRepo/SDP-DrPhil-Add-Door-Gazebo/ros-workspace/src/dr-phil/meshes/bases/waffle_pi_base_layer.stl</uri>
            </mesh>
          </geometry>
          <material>
            <script>
              <name>Gazebo/DarkGrey</name>
              <uri>file://media/materials/scripts/gazebo.material</uri>
            </script>
          </material>
        </visual>
        <visual name='base_footprint_fixed_joint_lump__px100/base_arm_visual_2'>
          <pose>0.01 0 0.152 0 -0 1.5708</pose>
          <geometry>
            <mesh>
              <scale>0.001 0.001 0.001</scale>
              <uri>/home/hwixley/Documents/Year3/SDP/GitRepo/SDP-DrPhil-Add-Door-Gazebo/ros-workspace/src/dr-phil/meshes/px100_meshes/px100_1_base.stl</uri>
            </mesh>
          </geometry>
        </visual>
        <visual name='base_footprint_fixed_joint_lump__base_scan_visual_3'>
          <pose>-0.064 0 0.132 0 -0 0</pose>
          <geometry>
            <mesh>
              <scale>0.001 0.001 0.001</scale>
              <uri>/home/hwixley/Documents/Year3/SDP/GitRepo/SDP-DrPhil-Add-Door-Gazebo/ros-workspace/src/dr-phil/meshes/sensors/lds.stl</uri>
            </mesh>
          </geometry>
          <material>
            <script>
              <name>Gazebo/FlatBlack</name>
              <uri>file://media/materials/scripts/gazebo.material</uri>
            </script>
          </material>
        </visual>
        <velocity_decay/>
        <velocity_decay/>
        <sensor name='Pi Camera' type='camera'>
          <always_on>1</always_on>
          <visualize>0</visualize>
          <camera>
            <horizontal_fov>1.0856</horizontal_fov>
            <image>
              <width>640</width>
              <height>480</height>
              <format>R8G8B8</format>
            </image>
            <clip>
              <near>0.03</near>
              <far>100</far>
            </clip>
          </camera>
          <plugin name='camera_controller' filename='libgazebo_ros_camera.so'>
            <alwaysOn>1</alwaysOn>
            <updateRate>30.0</updateRate>
            <cameraName>camera</cameraName>
            <frameName>camera_rgb_optical_frame</frameName>
            <imageTopicName>/image</imageTopicName>
            <cameraInfoTopicName>/camera_info</cameraInfoTopicName>
            <hackBaseline>0.07</hackBaseline>
            <distortionK1>0.0</distortionK1>
            <distortionK2>0.0</distortionK2>
            <distortionK3>0.0</distortionK3>
            <distortionT1>0.0</distortionT1>
            <distortionT2>0.0</distortionT2>
            <robotNamespace>/</robotNamespace>
          </plugin>
          <pose>0.076 0 0.103 0 -0 0</pose>
        </sensor>
        <velocity_decay/>
        <velocity_decay/>
        <velocity_decay/>
        <sensor name='imu' type='imu'>
          <always_on>1</always_on>
          <visualize>0</visualize>
          <pose>0 0 0.078 0 -0 0</pose>
          <imu/>
        </sensor>
        <gravity>1</gravity>
        <velocity_decay/>
        <sensor name='lds_lfcd_sensor' type='ray'>
          <visualize>0</visualize>
          <update_rate>5</update_rate>
          <ray>
            <scan>
              <horizontal>
                <samples>360</samples>
                <resolution>1</resolution>
                <min_angle>0</min_angle>
                <max_angle>6.28319</max_angle>
              </horizontal>
              <vertical>
                <samples>1</samples>
                <min_angle>0</min_angle>
                <max_angle>0</max_angle>
              </vertical>
            </scan>
            <range>
              <min>0.12</min>
              <max>3.5</max>
              <resolution>0.015</resolution>
            </range>
            <noise>
              <type>gaussian</type>
              <mean>0</mean>
              <stddev>0.01</stddev>
            </noise>
          </ray>
          <plugin name='gazebo_ros_lds_lfcd_controller' filename='libgazebo_ros_laser.so'>
            <topicName>scan</topicName>
            <frameName>base_scan</frameName>
            <robotNamespace>/</robotNamespace>
          </plugin>
          <pose>-0.064 0 0.132 0 -0 0</pose>
        </sensor>
        <self_collide>0</self_collide>
        <enable_wind>0</enable_wind>
        <kinematic>0</kinematic>
        <publishTf>1</publishTf>
      </link>
      <joint name='waist' type='revolute'>
        <pose relative_to='base_footprint'>0.01 0 0.20285 0 -0 0</pose>
        <parent>base_footprint</parent>
        <child>px100/shoulder_link</child>
        <axis>
          <xyz>0 0 1</xyz>
          <limit>
            <lower>-3.14158</lower>
            <upper>3.14158</upper>
            <effort>1</effort>
            <velocity>3.14159</velocity>
          </limit>
          <dynamics>
            <damping>0</damping>
            <friction>0.1</friction>
            <spring_reference>0</spring_reference>
            <spring_stiffness>0</spring_stiffness>
          </dynamics>
        </axis>
      </joint>
      <link name='px100/shoulder_link'>
        <pose relative_to='waist'>0 0 0 0 -0 0</pose>
        <inertial>
          <pose>1.1e-05 -0.000361 0.02846 0 -0 1.5708</pose>
          <mass>0.072587</mass>
          <inertia>
            <ixx>2.31e-05</ixx>
            <ixy>3e-10</ixy>
            <ixz>1.606e-07</ixz>
            <iyy>2.535e-05</iyy>
            <iyz>-2.06e-08</iyz>
            <izz>1.442e-05</izz>
          </inertia>
        </inertial>
        <collision name='px100/shoulder_link_collision'>
          <pose>0 0 -0.0022 0 -0 1.5708</pose>
          <geometry>
            <mesh>
              <scale>0.001 0.001 0.001</scale>
              <uri>/home/hwixley/Documents/Year3/SDP/GitRepo/SDP-DrPhil-Add-Door-Gazebo/ros-workspace/src/dr-phil/meshes/px100_meshes/px100_2_shoulder.stl</uri>
            </mesh>
          </geometry>
          <max_contacts>10</max_contacts>
          <surface>
            <contact>
              <ode/>
            </contact>
            <bounce/>
            <friction>
              <torsional>
                <ode/>
              </torsional>
              <ode/>
            </friction>
          </surface>
        </collision>
        <visual name='px100/shoulder_link_visual'>
          <pose>0 0 -0.0022 0 -0 1.5708</pose>
          <geometry>
            <mesh>
              <scale>0.001 0.001 0.001</scale>
              <uri>/home/hwixley/Documents/Year3/SDP/GitRepo/SDP-DrPhil-Add-Door-Gazebo/ros-workspace/src/dr-phil/meshes/px100_meshes/px100_2_shoulder.stl</uri>
            </mesh>
          </geometry>
        </visual>
        <self_collide>0</self_collide>
        <enable_wind>0</enable_wind>
        <kinematic>0</kinematic>
      </link>
      <joint name='shoulder' type='revolute'>
        <pose relative_to='px100/shoulder_link'>0 0 0.04225 0 -0 0</pose>
        <parent>px100/shoulder_link</parent>
        <child>px100/upper_arm_link</child>
        <axis>
          <xyz>0 1 0</xyz>
          <limit>
            <lower>-1.93732</lower>
            <upper>1.8675</upper>
            <effort>2</effort>
            <velocity>3.14159</velocity>
          </limit>
          <dynamics>
            <damping>0</damping>
            <friction>0.1</friction>
            <spring_reference>0</spring_reference>
            <spring_stiffness>0</spring_stiffness>
          </dynamics>
        </axis>
      </joint>
      <link name='px100/upper_arm_link'>
        <pose relative_to='shoulder'>0 0 0 0 -0 0</pose>
        <inertial>
          <pose>0.016198 -0.000293 0.087723 0 -0 1.5708</pose>
          <mass>0.082923</mass>
          <inertia>
            <ixx>8.006e-05</ixx>
            <ixy>-2.144e-07</ixy>
            <ixz>2.982e-07</ixz>
            <iyy>7.459e-05</iyy>
            <iyz>1.657e-05</iyz>
            <izz>3.685e-05</izz>
          </inertia>
        </inertial>
        <collision name='px100/upper_arm_link_collision'>
          <pose>0 0 0 0 -0 1.5708</pose>
          <geometry>
            <mesh>
              <scale>0.001 0.001 0.001</scale>
              <uri>/home/hwixley/Documents/Year3/SDP/GitRepo/SDP-DrPhil-Add-Door-Gazebo/ros-workspace/src/dr-phil/meshes/px100_meshes/px100_3_upper_arm.stl</uri>
            </mesh>
          </geometry>
          <max_contacts>10</max_contacts>
          <surface>
            <contact>
              <ode/>
            </contact>
            <bounce/>
            <friction>
              <torsional>
                <ode/>
              </torsional>
              <ode/>
            </friction>
          </surface>
        </collision>
        <visual name='px100/upper_arm_link_visual'>
          <pose>0 0 0 0 -0 1.5708</pose>
          <geometry>
            <mesh>
              <scale>0.001 0.001 0.001</scale>
              <uri>/home/hwixley/Documents/Year3/SDP/GitRepo/SDP-DrPhil-Add-Door-Gazebo/ros-workspace/src/dr-phil/meshes/px100_meshes/px100_3_upper_arm.stl</uri>
            </mesh>
          </geometry>
        </visual>
        <self_collide>0</self_collide>
        <enable_wind>0</enable_wind>
        <kinematic>0</kinematic>
      </link>
      <joint name='elbow' type='revolute'>
        <pose relative_to='px100/upper_arm_link'>0.035 0 0.1 0 -0 0</pose>
        <parent>px100/upper_arm_link</parent>
        <child>px100/forearm_link</child>
        <axis>
          <xyz>0 1 0</xyz>
          <limit>
            <lower>-2.11185</lower>
            <upper>1.6057</upper>
            <effort>2</effort>
            <velocity>3.14159</velocity>
          </limit>
          <dynamics>
            <damping>0</damping>
            <friction>0.1</friction>
            <spring_reference>0</spring_reference>
            <spring_stiffness>0</spring_stiffness>
          </dynamics>
        </axis>
      </joint>
      <link name='px100/forearm_link'>
        <pose relative_to='elbow'>0 0 0 0 -0 0</pose>
        <inertial>
          <pose>0.077372 -0.000332 0 0 -0 1.5708</pose>
          <mass>0.073058</mass>
          <inertia>
            <ixx>5.338e-05</ixx>
            <ixy>-3.073e-07</ixy>
            <ixz>0</ixz>
            <iyy>1.653e-05</iyy>
            <iyz>0</iyz>
            <izz>6.035e-05</izz>
          </inertia>
        </inertial>
        <collision name='px100/forearm_link_collision'>
          <pose>0 0 0 0 -0 1.5708</pose>
          <geometry>
            <mesh>
              <scale>0.001 0.001 0.001</scale>
              <uri>/home/hwixley/Documents/Year3/SDP/GitRepo/SDP-DrPhil-Add-Door-Gazebo/ros-workspace/src/dr-phil/meshes/px100_meshes/px100_4_forearm.stl</uri>
            </mesh>
          </geometry>
          <max_contacts>10</max_contacts>
          <surface>
            <contact>
              <ode/>
            </contact>
            <bounce/>
            <friction>
              <torsional>
                <ode/>
              </torsional>
              <ode/>
            </friction>
          </surface>
        </collision>
        <visual name='px100/forearm_link_visual'>
          <pose>0 0 0 0 -0 1.5708</pose>
          <geometry>
            <mesh>
              <scale>0.001 0.001 0.001</scale>
              <uri>/home/hwixley/Documents/Year3/SDP/GitRepo/SDP-DrPhil-Add-Door-Gazebo/ros-workspace/src/dr-phil/meshes/px100_meshes/px100_4_forearm.stl</uri>
            </mesh>
          </geometry>
        </visual>
        <self_collide>0</self_collide>
        <enable_wind>0</enable_wind>
        <kinematic>0</kinematic>
      </link>
      <joint name='wrist_angle' type='revolute'>
        <pose relative_to='px100/forearm_link'>0.1 0 0 0 -0 0</pose>
        <parent>px100/forearm_link</parent>
        <child>px100/gripper_link</child>
        <axis>
          <xyz>0 1 0</xyz>
          <limit>
            <lower>-1.74533</lower>
            <upper>2.14675</upper>
            <effort>1</effort>
            <velocity>3.14159</velocity>
          </limit>
          <dynamics>
            <damping>0</damping>
            <friction>0.1</friction>
            <spring_reference>0</spring_reference>
            <spring_stiffness>0</spring_stiffness>
          </dynamics>
        </axis>
      </joint>
      <link name='px100/gripper_link'>
        <pose relative_to='wrist_angle'>0 0 0 0 -0 0</pose>
        <inertial>
          <pose>0.054828 0 0.008995 0 -0 1.5708</pose>
          <mass>0.107128</mass>
          <inertia>
            <ixx>0.00305386</ixx>
            <ixy>-4.54306e-10</ixy>
            <ixz>-5.21925e-10</ixz>
            <iyy>0.00305006</iyy>
            <iyz>-5.55815e-06</iyz>
            <izz>0.00307092</izz>
          </inertia>
        </inertial>
        <collision name='px100/gripper_link_collision'>
          <pose>0 0 0 0 -0 1.5708</pose>
          <geometry>
            <mesh>
              <scale>0.001 0.001 0.001</scale>
              <uri>/home/hwixley/Documents/Year3/SDP/GitRepo/SDP-DrPhil-Add-Door-Gazebo/ros-workspace/src/dr-phil/meshes/px100_meshes/px100_5_gripper.stl</uri>
            </mesh>
          </geometry>
          <max_contacts>10</max_contacts>
          <surface>
            <contact>
              <ode/>
            </contact>
            <bounce/>
            <friction>
              <torsional>
                <ode/>
              </torsional>
              <ode/>
            </friction>
          </surface>
        </collision>
        <collision name='px100/gripper_link_fixed_joint_lump__px100/gripper_bar_link_collision_1'>
          <pose>0 0 0 0 -0 1.5708</pose>
          <geometry>
            <mesh>
              <scale>0.001 0.001 0.001</scale>
              <uri>/home/hwixley/Documents/Year3/SDP/GitRepo/SDP-DrPhil-Add-Door-Gazebo/ros-workspace/src/dr-phil/meshes/px100_meshes/px100_7_gripper_bar.stl</uri>
            </mesh>
          </geometry>
          <max_contacts>10</max_contacts>
          <surface>
            <contact>
              <ode/>
            </contact>
            <bounce/>
            <friction>
              <torsional>
                <ode/>
              </torsional>
              <ode/>
            </friction>
          </surface>
        </collision>
        <visual name='px100/gripper_link_visual'>
          <pose>0 0 0 0 -0 1.5708</pose>
          <geometry>
            <mesh>
              <scale>0.001 0.001 0.001</scale>
              <uri>/home/hwixley/Documents/Year3/SDP/GitRepo/SDP-DrPhil-Add-Door-Gazebo/ros-workspace/src/dr-phil/meshes/px100_meshes/px100_5_gripper.stl</uri>
            </mesh>
          </geometry>
        </visual>
        <visual name='px100/gripper_link_fixed_joint_lump__px100/gripper_bar_link_visual_1'>
          <pose>0 0 0 0 -0 1.5708</pose>
          <geometry>
            <mesh>
              <scale>0.001 0.001 0.001</scale>
              <uri>/home/hwixley/Documents/Year3/SDP/GitRepo/SDP-DrPhil-Add-Door-Gazebo/ros-workspace/src/dr-phil/meshes/px100_meshes/px100_7_gripper_bar.stl</uri>
            </mesh>
          </geometry>
        </visual>
        <self_collide>0</self_collide>
        <enable_wind>0</enable_wind>
        <kinematic>0</kinematic>
      </link>
      <joint name='gripper' type='revolute'>
        <pose relative_to='px100/gripper_link'>0.0685 0 0 0 -0 0</pose>
        <parent>px100/gripper_link</parent>
        <child>px100/gripper_prop_link</child>
        <axis>
          <xyz>1 0 0</xyz>
          <limit>
            <lower>-1e+16</lower>
            <upper>1e+16</upper>
          </limit>
          <dynamics>
            <damping>0</damping>
            <friction>0.1</friction>
            <spring_reference>0</spring_reference>
            <spring_stiffness>0</spring_stiffness>
          </dynamics>
        </axis>
      </joint>
      <link name='px100/gripper_prop_link'>
        <pose relative_to='gripper'>0 0 0 0 -0 0</pose>
        <inertial>
          <pose>0.000846 -2e-06 4.2e-05 0 -0 1.5708</pose>
          <mass>0.00434</mass>
          <inertia>
            <ixx>5.923e-07</ixx>
            <ixy>0</ixy>
            <ixz>3.195e-07</ixz>
            <iyy>1.1156e-06</iyy>
            <iyz>-4e-10</iyz>
            <izz>5.743e-07</izz>
          </inertia>
        </inertial>
        <collision name='px100/gripper_prop_link_collision'>
          <pose>-0.0685 0 0 0 -0 1.5708</pose>
          <geometry>
            <mesh>
              <scale>0.001 0.001 0.001</scale>
              <uri>/home/hwixley/Documents/Year3/SDP/GitRepo/SDP-DrPhil-Add-Door-Gazebo/ros-workspace/src/dr-phil/meshes/px100_meshes/px100_6_gripper_prop.stl</uri>
            </mesh>
          </geometry>
          <max_contacts>10</max_contacts>
          <surface>
            <contact>
              <ode/>
            </contact>
            <bounce/>
            <friction>
              <torsional>
                <ode/>
              </torsional>
              <ode/>
            </friction>
          </surface>
        </collision>
        <visual name='px100/gripper_prop_link_visual'>
          <pose>-0.0685 0 0 0 -0 1.5708</pose>
          <geometry>
            <mesh>
              <scale>0.001 0.001 0.001</scale>
              <uri>/home/hwixley/Documents/Year3/SDP/GitRepo/SDP-DrPhil-Add-Door-Gazebo/ros-workspace/src/dr-phil/meshes/px100_meshes/px100_6_gripper_prop.stl</uri>
            </mesh>
          </geometry>
        </visual>
        <self_collide>0</self_collide>
        <enable_wind>0</enable_wind>
        <kinematic>0</kinematic>
      </link>
      <joint name='left_finger' type='prismatic'>
        <pose relative_to='px100/gripper_link'>0.086 0 0 0 -0 0</pose>
        <parent>px100/gripper_link</parent>
        <child>px100/left_finger_link</child>
        <axis>
          <xyz>0 1 0</xyz>
          <limit>
            <lower>0.015</lower>
            <upper>0.037</upper>
            <effort>5</effort>
            <velocity>1</velocity>
          </limit>
          <dynamics>
            <damping>0</damping>
            <friction>0.1</friction>
            <spring_reference>0</spring_reference>
            <spring_stiffness>0</spring_stiffness>
          </dynamics>
        </axis>
      </joint>
      <link name='px100/left_finger_link'>
        <pose relative_to='left_finger'>0 0 0 0 -0 0</pose>
        <inertial>
          <pose>0.013816 0 0 0 0 -1.5708</pose>
          <mass>0.016246</mass>
          <inertia>
            <ixx>4.731e-06</ixx>
            <ixy>-4.56e-07</ixy>
            <ixz>0</ixz>
            <iyy>1.5506e-06</iyy>
            <iyz>0</iyz>
            <izz>3.7467e-06</izz>
          </inertia>
        </inertial>
        <collision name='px100/left_finger_link_collision'>
          <pose>0 0.005 0 0 -0 3.14159</pose>
          <geometry>
            <mesh>
              <scale>0.001 0.001 0.001</scale>
              <uri>/home/hwixley/Documents/Year3/SDP/GitRepo/SDP-DrPhil-Add-Door-Gazebo/ros-workspace/src/dr-phil/meshes/px100_meshes/px100_8_gripper_finger.stl</uri>
            </mesh>
          </geometry>
          <max_contacts>10</max_contacts>
          <surface>
            <contact>
              <ode/>
            </contact>
            <bounce/>
            <friction>
              <torsional>
                <ode/>
              </torsional>
              <ode/>
            </friction>
          </surface>
        </collision>
        <visual name='px100/left_finger_link_visual'>
          <pose>0 0.005 0 0 -0 3.14159</pose>
          <geometry>
            <mesh>
              <scale>0.001 0.001 0.001</scale>
              <uri>/home/hwixley/Documents/Year3/SDP/GitRepo/SDP-DrPhil-Add-Door-Gazebo/ros-workspace/src/dr-phil/meshes/px100_meshes/px100_8_gripper_finger.stl</uri>
            </mesh>
          </geometry>
        </visual>
        <self_collide>0</self_collide>
        <enable_wind>0</enable_wind>
        <kinematic>0</kinematic>
      </link>
      <joint name='right_finger' type='prismatic'>
        <pose relative_to='px100/gripper_link'>0.086 0 0 0 -0 0</pose>
        <parent>px100/gripper_link</parent>
        <child>px100/right_finger_link</child>
        <axis>
          <xyz>0 1 0</xyz>
          <limit>
            <lower>-0.037</lower>
            <upper>-0.015</upper>
            <effort>5</effort>
            <velocity>1</velocity>
          </limit>
          <dynamics>
            <damping>0</damping>
            <friction>0.1</friction>
            <spring_reference>0</spring_reference>
            <spring_stiffness>0</spring_stiffness>
          </dynamics>
        </axis>
      </joint>
      <link name='px100/right_finger_link'>
        <pose relative_to='right_finger'>0 0 0 0 -0 0</pose>
        <inertial>
          <pose>0.013816 0 0 3.14159 -0 -1.5708</pose>
          <mass>0.016246</mass>
          <inertia>
            <ixx>4.731e-06</ixx>
            <ixy>4.56e-07</ixy>
            <ixz>0</ixz>
            <iyy>1.5506e-06</iyy>
            <iyz>0</iyz>
            <izz>3.7467e-06</izz>
          </inertia>
        </inertial>
        <collision name='px100/right_finger_link_collision'>
          <pose>0 -0.005 0 3.14159 -0 3.14159</pose>
          <geometry>
            <mesh>
              <scale>0.001 0.001 0.001</scale>
              <uri>/home/hwixley/Documents/Year3/SDP/GitRepo/SDP-DrPhil-Add-Door-Gazebo/ros-workspace/src/dr-phil/meshes/px100_meshes/px100_8_gripper_finger.stl</uri>
            </mesh>
          </geometry>
          <max_contacts>10</max_contacts>
          <surface>
            <contact>
              <ode/>
            </contact>
            <bounce/>
            <friction>
              <torsional>
                <ode/>
              </torsional>
              <ode/>
            </friction>
          </surface>
        </collision>
        <visual name='px100/right_finger_link_visual'>
          <pose>0 -0.005 0 3.14159 -0 3.14159</pose>
          <geometry>
            <mesh>
              <scale>0.001 0.001 0.001</scale>
              <uri>/home/hwixley/Documents/Year3/SDP/GitRepo/SDP-DrPhil-Add-Door-Gazebo/ros-workspace/src/dr-phil/meshes/px100_meshes/px100_8_gripper_finger.stl</uri>
            </mesh>
          </geometry>
        </visual>
        <self_collide>0</self_collide>
        <enable_wind>0</enable_wind>
        <kinematic>0</kinematic>
      </link>
      <joint name='wheel_left_joint' type='revolute'>
        <pose relative_to='base_footprint'>0 0.144 0.033 -1.57 0 0</pose>
        <parent>base_footprint</parent>
        <child>wheel_left_link</child>
        <axis>
          <xyz>0 0 1</xyz>
          <limit>
            <lower>-1e+16</lower>
            <upper>1e+16</upper>
          </limit>
          <dynamics>
            <spring_reference>0</spring_reference>
            <spring_stiffness>0</spring_stiffness>
          </dynamics>
        </axis>
      </joint>
      <link name='wheel_left_link'>
        <pose relative_to='wheel_left_joint'>0 0 0 0 -0 0</pose>
        <inertial>
          <pose>0 0 0 0 -0 0</pose>
          <mass>0.0284989</mass>
          <inertia>
            <ixx>1.11756e-05</ixx>
            <ixy>-4.23698e-11</ixy>
            <ixz>-5.93817e-09</ixz>
            <iyy>1.11924e-05</iyy>
            <iyz>-1.44001e-11</iyz>
            <izz>2.07126e-05</izz>
          </inertia>
        </inertial>
        <collision name='wheel_left_link_collision'>
          <pose>0 0 0 0 -0 0</pose>
          <geometry>
            <cylinder>
              <length>0.018</length>
              <radius>0.033</radius>
            </cylinder>
          </geometry>
          <surface>
            <contact>
              <ode>
                <kp>500000</kp>
                <kd>10</kd>
                <max_vel>0.1</max_vel>
                <min_depth>0.001</min_depth>
              </ode>
            </contact>
            <friction>
              <ode>
                <mu>0.1</mu>
                <mu2>0.1</mu2>
                <fdir1>1 0 0</fdir1>
              </ode>
              <torsional>
                <ode/>
              </torsional>
            </friction>
            <bounce/>
          </surface>
          <max_contacts>10</max_contacts>
        </collision>
        <visual name='wheel_left_link_visual'>
          <pose>0 0 0 1.57 -0 0</pose>
          <geometry>
            <mesh>
              <scale>0.001 0.001 0.001</scale>
              <uri>/home/hwixley/Documents/Year3/SDP/GitRepo/SDP-DrPhil-Add-Door-Gazebo/ros-workspace/src/dr-phil/meshes/wheels/left_tire.stl</uri>
            </mesh>
          </geometry>
          <material>
            <script>
              <name>Gazebo/FlatBlack</name>
              <uri>file://media/materials/scripts/gazebo.material</uri>
            </script>
          </material>
        </visual>
        <gravity>1</gravity>
        <velocity_decay/>
        <self_collide>0</self_collide>
        <enable_wind>0</enable_wind>
        <kinematic>0</kinematic>
      </link>
      <joint name='wheel_right_joint' type='revolute'>
        <pose relative_to='base_footprint'>0 -0.144 0.033 -1.57 0 0</pose>
        <parent>base_footprint</parent>
        <child>wheel_right_link</child>
        <axis>
          <xyz>0 0 1</xyz>
          <limit>
            <lower>-1e+16</lower>
            <upper>1e+16</upper>
          </limit>
          <dynamics>
            <spring_reference>0</spring_reference>
            <spring_stiffness>0</spring_stiffness>
          </dynamics>
        </axis>
      </joint>
      <link name='wheel_right_link'>
        <pose relative_to='wheel_right_joint'>0 0 0 0 -0 0</pose>
        <inertial>
          <pose>0 0 0 0 -0 0</pose>
          <mass>0.0284989</mass>
          <inertia>
            <ixx>1.11756e-05</ixx>
            <ixy>-4.23698e-11</ixy>
            <ixz>-5.93817e-09</ixz>
            <iyy>1.11924e-05</iyy>
            <iyz>-1.44001e-11</iyz>
            <izz>2.07126e-05</izz>
          </inertia>
        </inertial>
        <collision name='wheel_right_link_collision'>
          <pose>0 0 0 0 -0 0</pose>
          <geometry>
            <cylinder>
              <length>0.018</length>
              <radius>0.033</radius>
            </cylinder>
          </geometry>
          <surface>
            <contact>
              <ode>
                <kp>500000</kp>
                <kd>10</kd>
                <max_vel>0.1</max_vel>
                <min_depth>0.001</min_depth>
              </ode>
            </contact>
            <friction>
              <ode>
                <mu>0.1</mu>
                <mu2>0.1</mu2>
                <fdir1>1 0 0</fdir1>
              </ode>
              <torsional>
                <ode/>
              </torsional>
            </friction>
            <bounce/>
          </surface>
          <max_contacts>10</max_contacts>
        </collision>
        <visual name='wheel_right_link_visual'>
          <pose>0 0 0 1.57 -0 0</pose>
          <geometry>
            <mesh>
              <scale>0.001 0.001 0.001</scale>
              <uri>/home/hwixley/Documents/Year3/SDP/GitRepo/SDP-DrPhil-Add-Door-Gazebo/ros-workspace/src/dr-phil/meshes/wheels/right_tire.stl</uri>
            </mesh>
          </geometry>
          <material>
            <script>
              <name>Gazebo/FlatBlack</name>
              <uri>file://media/materials/scripts/gazebo.material</uri>
            </script>
          </material>
        </visual>
        <gravity>1</gravity>
        <velocity_decay/>
        <self_collide>0</self_collide>
        <enable_wind>0</enable_wind>
        <kinematic>0</kinematic>
      </link>
      <plugin name='turtlebot3_waffle_pi_controller' filename='libgazebo_ros_diff_drive.so'>
        <commandTopic>cmd_vel</commandTopic>
        <odometryTopic>odom</odometryTopic>
        <odometryFrame>odom</odometryFrame>
        <odometrySource>world</odometrySource>
        <publishOdomTF>1</publishOdomTF>
        <robotBaseFrame>base_footprint</robotBaseFrame>
        <publishWheelTF>0</publishWheelTF>
        <publishTf>1</publishTf>
        <publishWheelJointState>1</publishWheelJointState>
        <legacyMode>0</legacyMode>
        <updateRate>30</updateRate>
        <leftJoint>wheel_left_joint</leftJoint>
        <rightJoint>wheel_right_joint</rightJoint>
        <wheelSeparation>0.287</wheelSeparation>
        <wheelDiameter>0.066</wheelDiameter>
        <wheelAcceleration>1</wheelAcceleration>
        <wheelTorque>10</wheelTorque>
        <rosDebugLevel>na</rosDebugLevel>
        <robotNamespace>/</robotNamespace>
      </plugin>
      <plugin name='imu_plugin' filename='libgazebo_ros_imu.so'>
        <alwaysOn>1</alwaysOn>
        <topicName>imu</topicName>
        <serviceName>imu_service</serviceName>
        <gaussianNoise>0.0</gaussianNoise>
        <updateRate>0</updateRate>
        <imu>
          <noise>
            <type>gaussian</type>
            <rate>
              <mean>0.0</mean>
              <stddev>2e-4</stddev>
              <bias_mean>0.0000075</bias_mean>
              <bias_stddev>0.0000008</bias_stddev>
            </rate>
            <accel>
              <mean>0.0</mean>
              <stddev>1.7e-2</stddev>
              <bias_mean>0.1</bias_mean>
              <bias_stddev>0.001</bias_stddev>
            </accel>
          </noise>
        </imu>
        <robotNamespace>/</robotNamespace>
        <bodyName>base_footprint</bodyName>
        <frameName>base_footprint</frameName>
        <xyzOffset>0 0 -0.156</xyzOffset>
        <rpyOffset>0 -0 0</rpyOffset>
      </plugin>
      <static>0</static>
      <plugin name='gazebo_ros_control' filename='libgazebo_ros_control.so'>
        <robotNamespace>/</robotNamespace>
      </plugin>
      <pose>-2 -0.5 0 0 -0 0</pose>
    </model>
  </world>
</sdf>
